[2025-03-19T15:15:29.409+0000] {taskinstance.py:1157} INFO - Dependencies all met for dep_context=non-requeueable deps ti=<TaskInstance: faud_detection_pipeline.store_data_hdfs scheduled__2023-10-02T00:00:00+00:00 [queued]>
[2025-03-19T15:15:29.582+0000] {taskinstance.py:1157} INFO - Dependencies all met for dep_context=requeueable deps ti=<TaskInstance: faud_detection_pipeline.store_data_hdfs scheduled__2023-10-02T00:00:00+00:00 [queued]>
[2025-03-19T15:15:29.596+0000] {taskinstance.py:1359} INFO - Starting attempt 1 of 2
[2025-03-19T15:15:29.814+0000] {taskinstance.py:1380} INFO - Executing <Task(BashOperator): store_data_hdfs> on 2023-10-02 00:00:00+00:00
[2025-03-19T15:15:29.895+0000] {standard_task_runner.py:84} INFO - Running: ['***', 'tasks', 'run', 'faud_detection_pipeline', 'store_data_hdfs', 'scheduled__2023-10-02T00:00:00+00:00', '--job-id', '1261', '--raw', '--subdir', 'DAGS_FOLDER/dag_1.py', '--cfg-path', '/tmp/tmpaq6tv4yl']
[2025-03-19T15:15:29.915+0000] {standard_task_runner.py:85} INFO - Job 1261: Subtask store_data_hdfs
[2025-03-19T15:15:29.865+0000] {standard_task_runner.py:57} INFO - Started process 9750 to run task
[2025-03-19T15:15:30.343+0000] {task_command.py:415} INFO - Running <TaskInstance: faud_detection_pipeline.store_data_hdfs scheduled__2023-10-02T00:00:00+00:00 [running]> on host 0009f5fb76aa
[2025-03-19T15:15:30.788+0000] {taskinstance.py:1660} INFO - Exporting env vars: AIRFLOW_CTX_DAG_OWNER='***' AIRFLOW_CTX_DAG_ID='faud_detection_pipeline' AIRFLOW_CTX_TASK_ID='store_data_hdfs' AIRFLOW_CTX_EXECUTION_DATE='2023-10-02T00:00:00+00:00' AIRFLOW_CTX_TRY_NUMBER='1' AIRFLOW_CTX_DAG_RUN_ID='scheduled__2023-10-02T00:00:00+00:00'
[2025-03-19T15:15:30.806+0000] {subprocess.py:63} INFO - Tmp dir root location: /tmp
[2025-03-19T15:15:30.814+0000] {subprocess.py:75} INFO - Running command: ['/bin/bash', '-c', 'docker cp /tmp/transactions.json namenode:/tmp/transactions.json && docker cp /tmp/customers.json namenode:/tmp/customers.json && docker cp /tmp/external_data.json namenode:/tmp/external_data.json && docker exec namenode bash -c "hdfs dfs -mkdir -p /data && hdfs dfs -put -f /tmp/transactions.json /data/transactions/transactions.json && hdfs dfs -put -f /tmp/customers.json /data/customers/customers.json && hdfs dfs -put -f /tmp/external_data.json /data/external_data/external_data.json  "']
[2025-03-19T15:15:30.942+0000] {subprocess.py:86} INFO - Output:
[2025-03-19T15:16:01.403+0000] {subprocess.py:93} INFO - put: `/data/transactions/transactions.json': No such file or directory: `hdfs://namenode:9000/data/transactions/transactions.json'
[2025-03-19T15:16:02.159+0000] {subprocess.py:97} INFO - Command exited with return code 1
[2025-03-19T15:16:02.221+0000] {taskinstance.py:1935} ERROR - Task failed with exception
Traceback (most recent call last):
  File "/home/airflow/.local/lib/python3.8/site-packages/airflow/operators/bash.py", line 210, in execute
    raise AirflowException(
airflow.exceptions.AirflowException: Bash command failed. The command returned a non-zero exit code 1.
[2025-03-19T15:16:02.234+0000] {taskinstance.py:1398} INFO - Marking task as UP_FOR_RETRY. dag_id=faud_detection_pipeline, task_id=store_data_hdfs, execution_date=20231002T000000, start_date=20250319T151529, end_date=20250319T151602
[2025-03-19T15:16:02.755+0000] {standard_task_runner.py:104} ERROR - Failed to execute job 1261 for task store_data_hdfs (Bash command failed. The command returned a non-zero exit code 1.; 9750)
[2025-03-19T15:16:02.818+0000] {local_task_job_runner.py:228} INFO - Task exited with return code 1
[2025-03-19T15:16:03.032+0000] {taskinstance.py:2776} INFO - 0 downstream tasks scheduled from follow-on schedule check
