[2025-03-19T15:27:49.151+0000] {taskinstance.py:1157} INFO - Dependencies all met for dep_context=non-requeueable deps ti=<TaskInstance: faud_detection_pipeline.store_data_hdfs scheduled__2023-10-02T12:00:00+00:00 [queued]>
[2025-03-19T15:27:49.174+0000] {taskinstance.py:1157} INFO - Dependencies all met for dep_context=requeueable deps ti=<TaskInstance: faud_detection_pipeline.store_data_hdfs scheduled__2023-10-02T12:00:00+00:00 [queued]>
[2025-03-19T15:27:49.175+0000] {taskinstance.py:1359} INFO - Starting attempt 2 of 2
[2025-03-19T15:27:49.207+0000] {taskinstance.py:1380} INFO - Executing <Task(BashOperator): store_data_hdfs> on 2023-10-02 12:00:00+00:00
[2025-03-19T15:27:49.216+0000] {standard_task_runner.py:57} INFO - Started process 12109 to run task
[2025-03-19T15:27:49.222+0000] {standard_task_runner.py:84} INFO - Running: ['***', 'tasks', 'run', 'faud_detection_pipeline', 'store_data_hdfs', 'scheduled__2023-10-02T12:00:00+00:00', '--job-id', '1341', '--raw', '--subdir', 'DAGS_FOLDER/dag_1.py', '--cfg-path', '/tmp/tmpda_wutrz']
[2025-03-19T15:27:49.231+0000] {standard_task_runner.py:85} INFO - Job 1341: Subtask store_data_hdfs
[2025-03-19T15:27:49.344+0000] {task_command.py:415} INFO - Running <TaskInstance: faud_detection_pipeline.store_data_hdfs scheduled__2023-10-02T12:00:00+00:00 [running]> on host 0009f5fb76aa
[2025-03-19T15:27:49.506+0000] {taskinstance.py:1660} INFO - Exporting env vars: AIRFLOW_CTX_DAG_OWNER='***' AIRFLOW_CTX_DAG_ID='faud_detection_pipeline' AIRFLOW_CTX_TASK_ID='store_data_hdfs' AIRFLOW_CTX_EXECUTION_DATE='2023-10-02T12:00:00+00:00' AIRFLOW_CTX_TRY_NUMBER='2' AIRFLOW_CTX_DAG_RUN_ID='scheduled__2023-10-02T12:00:00+00:00'
[2025-03-19T15:27:49.509+0000] {subprocess.py:63} INFO - Tmp dir root location: /tmp
[2025-03-19T15:27:49.512+0000] {subprocess.py:75} INFO - Running command: ['/bin/bash', '-c', 'docker cp /tmp/transactions.json namenode:/tmp/transactions.json && docker cp /tmp/customers.json namenode:/tmp/customers.json && docker cp /tmp/external_data.json namenode:/tmp/external_data.json && docker exec namenode bash -c "hdfs dfs -mkdir -p /data/transactions && hdfs dfs -mkdir -p /data/customers && hdfs dfs -mkdir -p /data/external_data && hdfs dfs -put -f /tmp/transactions.json /data/transactions/transactions.json && hdfs dfs -put -f /tmp/customers.json /data/customers/customers.json && hdfs dfs -put -f /tmp/external_data.json /data/external_data/external_data.json && rm -rf /tmp/transactions.json /tmp/customers.json /tmp/external_data.json"']
[2025-03-19T15:27:49.541+0000] {subprocess.py:86} INFO - Output:
[2025-03-19T15:38:00.621+0000] {subprocess.py:93} INFO - 2025-03-19 15:38:00,614 INFO sasl.SaslDataTransferClient: SASL encryption trust check: localHostTrusted = false, remoteHostTrusted = false
[2025-03-19T15:38:23.091+0000] {subprocess.py:93} INFO - 2025-03-19 15:38:23,087 INFO sasl.SaslDataTransferClient: SASL encryption trust check: localHostTrusted = false, remoteHostTrusted = false
[2025-03-19T15:38:31.105+0000] {local_task_job_runner.py:294} WARNING - State of this instance has been externally set to failed. Terminating instance.
[2025-03-19T15:38:31.118+0000] {process_utils.py:131} INFO - Sending 15 to group 12109. PIDs of all processes in the group: [12110, 12109]
[2025-03-19T15:38:31.120+0000] {process_utils.py:86} INFO - Sending the signal 15 to group 12109
[2025-03-19T15:38:31.123+0000] {taskinstance.py:1630} ERROR - Received SIGTERM. Terminating subprocesses.
[2025-03-19T15:38:31.126+0000] {subprocess.py:104} INFO - Sending SIGTERM signal to process group
[2025-03-19T15:38:31.300+0000] {process_utils.py:79} INFO - Process psutil.Process(pid=12109, status='terminated', exitcode=0, started='15:27:48') (12109) terminated with exit code 0
[2025-03-19T15:38:31.306+0000] {process_utils.py:79} INFO - Process psutil.Process(pid=12110, status='terminated', started='15:27:48') (12110) terminated with exit code None
