[2025-03-19T11:31:45.659+0000] {taskinstance.py:1157} INFO - Dependencies all met for dep_context=non-requeueable deps ti=<TaskInstance: fraud_detection_pipeline.store_data_hdfs scheduled__2023-10-03T00:00:00+00:00 [queued]>
[2025-03-19T11:31:45.672+0000] {taskinstance.py:1157} INFO - Dependencies all met for dep_context=requeueable deps ti=<TaskInstance: fraud_detection_pipeline.store_data_hdfs scheduled__2023-10-03T00:00:00+00:00 [queued]>
[2025-03-19T11:31:45.673+0000] {taskinstance.py:1359} INFO - Starting attempt 2 of 2
[2025-03-19T11:31:45.694+0000] {taskinstance.py:1380} INFO - Executing <Task(BashOperator): store_data_hdfs> on 2023-10-03 00:00:00+00:00
[2025-03-19T11:31:45.702+0000] {standard_task_runner.py:57} INFO - Started process 5354 to run task
[2025-03-19T11:31:45.706+0000] {standard_task_runner.py:84} INFO - Running: ['***', 'tasks', 'run', 'fraud_detection_pipeline', 'store_data_hdfs', 'scheduled__2023-10-03T00:00:00+00:00', '--job-id', '151', '--raw', '--subdir', 'DAGS_FOLDER/dag_1.py', '--cfg-path', '/tmp/tmpo9g1maru']
[2025-03-19T11:31:45.710+0000] {standard_task_runner.py:85} INFO - Job 151: Subtask store_data_hdfs
[2025-03-19T11:31:45.782+0000] {task_command.py:415} INFO - Running <TaskInstance: fraud_detection_pipeline.store_data_hdfs scheduled__2023-10-03T00:00:00+00:00 [running]> on host 0009f5fb76aa
[2025-03-19T11:31:45.891+0000] {taskinstance.py:1660} INFO - Exporting env vars: AIRFLOW_CTX_DAG_OWNER='***' AIRFLOW_CTX_DAG_ID='fraud_detection_pipeline' AIRFLOW_CTX_TASK_ID='store_data_hdfs' AIRFLOW_CTX_EXECUTION_DATE='2023-10-03T00:00:00+00:00' AIRFLOW_CTX_TRY_NUMBER='2' AIRFLOW_CTX_DAG_RUN_ID='scheduled__2023-10-03T00:00:00+00:00'
[2025-03-19T11:31:45.894+0000] {subprocess.py:63} INFO - Tmp dir root location: /tmp
[2025-03-19T11:31:45.896+0000] {subprocess.py:75} INFO - Running command: ['/bin/bash', '-c', 'hdfs dfs -put /tmp/transactions.json /data/transactions.json && hdfs dfs -put /tmp/customers.json /data/customers.json && hdfs dfs -put /tmp/external_data.json /data/external_data.json']
[2025-03-19T11:31:45.914+0000] {subprocess.py:86} INFO - Output:
[2025-03-19T11:31:45.917+0000] {subprocess.py:93} INFO - /bin/bash: line 1: hdfs: command not found
[2025-03-19T11:31:45.918+0000] {subprocess.py:97} INFO - Command exited with return code 127
[2025-03-19T11:31:45.935+0000] {taskinstance.py:1935} ERROR - Task failed with exception
Traceback (most recent call last):
  File "/home/airflow/.local/lib/python3.8/site-packages/airflow/operators/bash.py", line 210, in execute
    raise AirflowException(
airflow.exceptions.AirflowException: Bash command failed. The command returned a non-zero exit code 127.
[2025-03-19T11:31:45.941+0000] {taskinstance.py:1398} INFO - Marking task as FAILED. dag_id=fraud_detection_pipeline, task_id=store_data_hdfs, execution_date=20231003T000000, start_date=20250319T113145, end_date=20250319T113145
[2025-03-19T11:31:46.195+0000] {standard_task_runner.py:104} ERROR - Failed to execute job 151 for task store_data_hdfs (Bash command failed. The command returned a non-zero exit code 127.; 5354)
[2025-03-19T11:31:46.245+0000] {local_task_job_runner.py:228} INFO - Task exited with return code 1
[2025-03-19T11:31:46.303+0000] {taskinstance.py:2776} INFO - 0 downstream tasks scheduled from follow-on schedule check
