[2025-03-19T21:10:20.781+0000] {taskinstance.py:1157} INFO - Dependencies all met for dep_context=non-requeueable deps ti=<TaskInstance: faud_detection_pipeline.store_data_hdfs scheduled__2023-10-21T10:00:00+00:00 [queued]>
[2025-03-19T21:10:20.835+0000] {taskinstance.py:1157} INFO - Dependencies all met for dep_context=requeueable deps ti=<TaskInstance: faud_detection_pipeline.store_data_hdfs scheduled__2023-10-21T10:00:00+00:00 [queued]>
[2025-03-19T21:10:20.851+0000] {taskinstance.py:1359} INFO - Starting attempt 1 of 1
[2025-03-19T21:10:21.027+0000] {taskinstance.py:1380} INFO - Executing <Task(BashOperator): store_data_hdfs> on 2023-10-21 10:00:00+00:00
[2025-03-19T21:10:21.075+0000] {standard_task_runner.py:84} INFO - Running: ['***', 'tasks', 'run', 'faud_detection_pipeline', 'store_data_hdfs', 'scheduled__2023-10-21T10:00:00+00:00', '--job-id', '3069', '--raw', '--subdir', 'DAGS_FOLDER/dag_1.py', '--cfg-path', '/tmp/tmpws05klfm']
[2025-03-19T21:10:21.090+0000] {standard_task_runner.py:85} INFO - Job 3069: Subtask store_data_hdfs
[2025-03-19T21:10:21.072+0000] {standard_task_runner.py:57} INFO - Started process 3072 to run task
[2025-03-19T21:10:21.410+0000] {task_command.py:415} INFO - Running <TaskInstance: faud_detection_pipeline.store_data_hdfs scheduled__2023-10-21T10:00:00+00:00 [running]> on host 445fc0f18383
[2025-03-19T21:10:22.004+0000] {taskinstance.py:1660} INFO - Exporting env vars: AIRFLOW_CTX_DAG_OWNER='***' AIRFLOW_CTX_DAG_ID='faud_detection_pipeline' AIRFLOW_CTX_TASK_ID='store_data_hdfs' AIRFLOW_CTX_EXECUTION_DATE='2023-10-21T10:00:00+00:00' AIRFLOW_CTX_TRY_NUMBER='1' AIRFLOW_CTX_DAG_RUN_ID='scheduled__2023-10-21T10:00:00+00:00'
[2025-03-19T21:10:22.015+0000] {subprocess.py:63} INFO - Tmp dir root location: /tmp
[2025-03-19T21:10:22.028+0000] {subprocess.py:75} INFO - Running command: ['/bin/bash', '-c', 'docker cp /tmp/transactions.csv namenode:/tmp/transactions.csv && docker cp /tmp/customers.csv namenode:/tmp/customers.csv && docker cp /tmp/external_data.csv namenode:/tmp/external_data.csv && docker exec namenode bash -c "hdfs dfs -mkdir -p /data/transactions && hdfs dfs -mkdir -p /data/customers && hdfs dfs -mkdir -p /data/external_data && hdfs dfs -put -f /tmp/transactions.csv /data/transactions/transactions.csv && hdfs dfs -put -f /tmp/customers.csv /data/customers/customers.csv && hdfs dfs -put -f /tmp/external_data.csv /data/external_data/external_data.csv && rm -rf /tmp/transactions.csv /tmp/customers.csv /tmp/external_data.csv"']
[2025-03-19T21:10:22.084+0000] {subprocess.py:86} INFO - Output:
[2025-03-19T21:11:23.541+0000] {subprocess.py:93} INFO - 2025-03-19 21:11:23,538 INFO sasl.SaslDataTransferClient: SASL encryption trust check: localHostTrusted = false, remoteHostTrusted = false
[2025-03-19T21:11:24.082+0000] {subprocess.py:93} INFO - put: File does not exist: /data/transactions/transactions.csv._COPYING_ (inode 17983) Holder DFSClient_NONMAPREDUCE_-31586382_1 does not have any open files.
[2025-03-19T21:11:24.519+0000] {subprocess.py:97} INFO - Command exited with return code 1
[2025-03-19T21:11:24.558+0000] {taskinstance.py:1935} ERROR - Task failed with exception
Traceback (most recent call last):
  File "/home/airflow/.local/lib/python3.8/site-packages/airflow/operators/bash.py", line 210, in execute
    raise AirflowException(
airflow.exceptions.AirflowException: Bash command failed. The command returned a non-zero exit code 1.
[2025-03-19T21:11:24.567+0000] {taskinstance.py:1398} INFO - Marking task as FAILED. dag_id=faud_detection_pipeline, task_id=store_data_hdfs, execution_date=20231021T100000, start_date=20250319T211020, end_date=20250319T211124
[2025-03-19T21:11:24.695+0000] {standard_task_runner.py:104} ERROR - Failed to execute job 3069 for task store_data_hdfs (Bash command failed. The command returned a non-zero exit code 1.; 3072)
[2025-03-19T21:11:24.745+0000] {local_task_job_runner.py:228} INFO - Task exited with return code 1
[2025-03-19T21:11:24.811+0000] {taskinstance.py:2776} INFO - 0 downstream tasks scheduled from follow-on schedule check
