[2025-03-19T17:36:59.764+0000] {taskinstance.py:1157} INFO - Dependencies all met for dep_context=non-requeueable deps ti=<TaskInstance: faud_detection_pipeline.store_data_hdfs scheduled__2023-10-14T02:00:00+00:00 [queued]>
[2025-03-19T17:36:59.783+0000] {taskinstance.py:1157} INFO - Dependencies all met for dep_context=requeueable deps ti=<TaskInstance: faud_detection_pipeline.store_data_hdfs scheduled__2023-10-14T02:00:00+00:00 [queued]>
[2025-03-19T17:36:59.784+0000] {taskinstance.py:1359} INFO - Starting attempt 1 of 2
[2025-03-19T17:36:59.813+0000] {taskinstance.py:1380} INFO - Executing <Task(BashOperator): store_data_hdfs> on 2023-10-14 02:00:00+00:00
[2025-03-19T17:36:59.822+0000] {standard_task_runner.py:57} INFO - Started process 35864 to run task
[2025-03-19T17:36:59.828+0000] {standard_task_runner.py:84} INFO - Running: ['***', 'tasks', 'run', 'faud_detection_pipeline', 'store_data_hdfs', 'scheduled__2023-10-14T02:00:00+00:00', '--job-id', '2422', '--raw', '--subdir', 'DAGS_FOLDER/dag_1.py', '--cfg-path', '/tmp/tmp3my9axkk']
[2025-03-19T17:36:59.832+0000] {standard_task_runner.py:85} INFO - Job 2422: Subtask store_data_hdfs
[2025-03-19T17:36:59.920+0000] {task_command.py:415} INFO - Running <TaskInstance: faud_detection_pipeline.store_data_hdfs scheduled__2023-10-14T02:00:00+00:00 [running]> on host 0009f5fb76aa
[2025-03-19T17:37:00.100+0000] {taskinstance.py:1660} INFO - Exporting env vars: AIRFLOW_CTX_DAG_OWNER='***' AIRFLOW_CTX_DAG_ID='faud_detection_pipeline' AIRFLOW_CTX_TASK_ID='store_data_hdfs' AIRFLOW_CTX_EXECUTION_DATE='2023-10-14T02:00:00+00:00' AIRFLOW_CTX_TRY_NUMBER='1' AIRFLOW_CTX_DAG_RUN_ID='scheduled__2023-10-14T02:00:00+00:00'
[2025-03-19T17:37:00.104+0000] {subprocess.py:63} INFO - Tmp dir root location: /tmp
[2025-03-19T17:37:00.106+0000] {subprocess.py:75} INFO - Running command: ['/bin/bash', '-c', 'docker cp /tmp/transactions.csv namenode:/tmp/transactions.csv && docker cp /tmp/customers.csv namenode:/tmp/customers.csv && docker cp /tmp/external_data.csv namenode:/tmp/external_data.csv && docker exec namenode bash -c "hdfs dfs -mkdir -p /data/transactions && hdfs dfs -mkdir -p /data/customers && hdfs dfs -mkdir -p /data/external_data && hdfs dfs -put -f /tmp/transactions.csv /data/transactions/transactions.csv && hdfs dfs -put -f /tmp/customers.csv /data/customers/customers.csv && hdfs dfs -put -f /tmp/external_data.csv /data/external_data/external_data.csv && rm -rf /tmp/transactions.csv /tmp/customers.csv /tmp/external_data.csv"']
[2025-03-19T17:37:00.133+0000] {subprocess.py:86} INFO - Output:
[2025-03-19T17:37:15.189+0000] {subprocess.py:93} INFO - 2025-03-19 17:37:15,180 WARN hdfs.DataStreamer: DataStreamer Exception
[2025-03-19T17:37:15.191+0000] {subprocess.py:93} INFO - java.io.FileNotFoundException: File does not exist: /data/transactions/transactions.csv._COPYING_ (inode 17589) Holder DFSClient_NONMAPREDUCE_-1183607247_1 does not have any open files.
[2025-03-19T17:37:15.192+0000] {subprocess.py:93} INFO - 	at org.apache.hadoop.hdfs.server.namenode.FSNamesystem.checkLease(FSNamesystem.java:2898)
[2025-03-19T17:37:15.193+0000] {subprocess.py:93} INFO - 	at org.apache.hadoop.hdfs.server.namenode.FSDirWriteFileOp.analyzeFileState(FSDirWriteFileOp.java:599)
[2025-03-19T17:37:15.194+0000] {subprocess.py:93} INFO - 	at org.apache.hadoop.hdfs.server.namenode.FSDirWriteFileOp.validateAddBlock(FSDirWriteFileOp.java:171)
[2025-03-19T17:37:15.195+0000] {subprocess.py:93} INFO - 	at org.apache.hadoop.hdfs.server.namenode.FSNamesystem.getAdditionalBlock(FSNamesystem.java:2777)
[2025-03-19T17:37:15.196+0000] {subprocess.py:93} INFO - 	at org.apache.hadoop.hdfs.server.namenode.NameNodeRpcServer.addBlock(NameNodeRpcServer.java:892)
[2025-03-19T17:37:15.197+0000] {subprocess.py:93} INFO - 	at org.apache.hadoop.hdfs.protocolPB.ClientNamenodeProtocolServerSideTranslatorPB.addBlock(ClientNamenodeProtocolServerSideTranslatorPB.java:574)
[2025-03-19T17:37:15.198+0000] {subprocess.py:93} INFO - 	at org.apache.hadoop.hdfs.protocol.proto.ClientNamenodeProtocolProtos$ClientNamenodeProtocol$2.callBlockingMethod(ClientNamenodeProtocolProtos.java)
[2025-03-19T17:37:15.198+0000] {subprocess.py:93} INFO - 	at org.apache.hadoop.ipc.ProtobufRpcEngine$Server$ProtoBufRpcInvoker.call(ProtobufRpcEngine.java:528)
[2025-03-19T17:37:15.199+0000] {subprocess.py:93} INFO - 	at org.apache.hadoop.ipc.RPC$Server.call(RPC.java:1070)
[2025-03-19T17:37:15.200+0000] {subprocess.py:93} INFO - 	at org.apache.hadoop.ipc.Server$RpcCall.run(Server.java:999)
[2025-03-19T17:37:15.200+0000] {subprocess.py:93} INFO - 	at org.apache.hadoop.ipc.Server$RpcCall.run(Server.java:927)
[2025-03-19T17:37:15.201+0000] {subprocess.py:93} INFO - 	at java.security.AccessController.doPrivileged(Native Method)
[2025-03-19T17:37:15.201+0000] {subprocess.py:93} INFO - 	at javax.security.auth.Subject.doAs(Subject.java:422)
[2025-03-19T17:37:15.204+0000] {subprocess.py:93} INFO - 	at org.apache.hadoop.security.UserGroupInformation.doAs(UserGroupInformation.java:1730)
[2025-03-19T17:37:15.205+0000] {subprocess.py:93} INFO - 	at org.apache.hadoop.ipc.Server$Handler.run(Server.java:2915)
[2025-03-19T17:37:15.206+0000] {subprocess.py:93} INFO - 
[2025-03-19T17:37:15.207+0000] {subprocess.py:93} INFO - 	at sun.reflect.NativeConstructorAccessorImpl.newInstance0(Native Method)
[2025-03-19T17:37:15.210+0000] {subprocess.py:93} INFO - 	at sun.reflect.NativeConstructorAccessorImpl.newInstance(NativeConstructorAccessorImpl.java:62)
[2025-03-19T17:37:15.212+0000] {subprocess.py:93} INFO - 	at sun.reflect.DelegatingConstructorAccessorImpl.newInstance(DelegatingConstructorAccessorImpl.java:45)
[2025-03-19T17:37:15.214+0000] {subprocess.py:93} INFO - 	at java.lang.reflect.Constructor.newInstance(Constructor.java:423)
[2025-03-19T17:37:15.215+0000] {subprocess.py:93} INFO - 	at org.apache.hadoop.ipc.RemoteException.instantiateException(RemoteException.java:121)
[2025-03-19T17:37:15.216+0000] {subprocess.py:93} INFO - 	at org.apache.hadoop.ipc.RemoteException.unwrapRemoteException(RemoteException.java:88)
[2025-03-19T17:37:15.217+0000] {subprocess.py:93} INFO - 	at org.apache.hadoop.hdfs.DFSOutputStream.addBlock(DFSOutputStream.java:1084)
[2025-03-19T17:37:15.218+0000] {subprocess.py:93} INFO - 	at org.apache.hadoop.hdfs.DataStreamer.locateFollowingBlock(DataStreamer.java:1866)
[2025-03-19T17:37:15.218+0000] {subprocess.py:93} INFO - 	at org.apache.hadoop.hdfs.DataStreamer.nextBlockOutputStream(DataStreamer.java:1668)
[2025-03-19T17:37:15.219+0000] {subprocess.py:93} INFO - 	at org.apache.hadoop.hdfs.DataStreamer.run(DataStreamer.java:716)
[2025-03-19T17:37:15.219+0000] {subprocess.py:93} INFO - Caused by: org.apache.hadoop.ipc.RemoteException(java.io.FileNotFoundException): File does not exist: /data/transactions/transactions.csv._COPYING_ (inode 17589) Holder DFSClient_NONMAPREDUCE_-1183607247_1 does not have any open files.
[2025-03-19T17:37:15.220+0000] {subprocess.py:93} INFO - 	at org.apache.hadoop.hdfs.server.namenode.FSNamesystem.checkLease(FSNamesystem.java:2898)
[2025-03-19T17:37:15.221+0000] {subprocess.py:93} INFO - 	at org.apache.hadoop.hdfs.server.namenode.FSDirWriteFileOp.analyzeFileState(FSDirWriteFileOp.java:599)
[2025-03-19T17:37:15.221+0000] {subprocess.py:93} INFO - 	at org.apache.hadoop.hdfs.server.namenode.FSDirWriteFileOp.validateAddBlock(FSDirWriteFileOp.java:171)
[2025-03-19T17:37:15.222+0000] {subprocess.py:93} INFO - 	at org.apache.hadoop.hdfs.server.namenode.FSNamesystem.getAdditionalBlock(FSNamesystem.java:2777)
[2025-03-19T17:37:15.222+0000] {subprocess.py:93} INFO - 	at org.apache.hadoop.hdfs.server.namenode.NameNodeRpcServer.addBlock(NameNodeRpcServer.java:892)
[2025-03-19T17:37:15.223+0000] {subprocess.py:93} INFO - 	at org.apache.hadoop.hdfs.protocolPB.ClientNamenodeProtocolServerSideTranslatorPB.addBlock(ClientNamenodeProtocolServerSideTranslatorPB.java:574)
[2025-03-19T17:37:15.223+0000] {subprocess.py:93} INFO - 	at org.apache.hadoop.hdfs.protocol.proto.ClientNamenodeProtocolProtos$ClientNamenodeProtocol$2.callBlockingMethod(ClientNamenodeProtocolProtos.java)
[2025-03-19T17:37:15.223+0000] {subprocess.py:93} INFO - 	at org.apache.hadoop.ipc.ProtobufRpcEngine$Server$ProtoBufRpcInvoker.call(ProtobufRpcEngine.java:528)
[2025-03-19T17:37:15.224+0000] {subprocess.py:93} INFO - 	at org.apache.hadoop.ipc.RPC$Server.call(RPC.java:1070)
[2025-03-19T17:37:15.224+0000] {subprocess.py:93} INFO - 	at org.apache.hadoop.ipc.Server$RpcCall.run(Server.java:999)
[2025-03-19T17:37:15.225+0000] {subprocess.py:93} INFO - 	at org.apache.hadoop.ipc.Server$RpcCall.run(Server.java:927)
[2025-03-19T17:37:15.225+0000] {subprocess.py:93} INFO - 	at java.security.AccessController.doPrivileged(Native Method)
[2025-03-19T17:37:15.225+0000] {subprocess.py:93} INFO - 	at javax.security.auth.Subject.doAs(Subject.java:422)
[2025-03-19T17:37:15.227+0000] {subprocess.py:93} INFO - 	at org.apache.hadoop.security.UserGroupInformation.doAs(UserGroupInformation.java:1730)
[2025-03-19T17:37:15.228+0000] {subprocess.py:93} INFO - 	at org.apache.hadoop.ipc.Server$Handler.run(Server.java:2915)
[2025-03-19T17:37:15.235+0000] {subprocess.py:93} INFO - 
[2025-03-19T17:37:15.237+0000] {subprocess.py:93} INFO - 	at org.apache.hadoop.ipc.Client.getRpcResponse(Client.java:1545)
[2025-03-19T17:37:15.238+0000] {subprocess.py:93} INFO - 	at org.apache.hadoop.ipc.Client.call(Client.java:1491)
[2025-03-19T17:37:15.240+0000] {subprocess.py:93} INFO - 	at org.apache.hadoop.ipc.Client.call(Client.java:1388)
[2025-03-19T17:37:15.242+0000] {subprocess.py:93} INFO - 	at org.apache.hadoop.ipc.ProtobufRpcEngine$Invoker.invoke(ProtobufRpcEngine.java:233)
[2025-03-19T17:37:15.255+0000] {subprocess.py:93} INFO - 	at org.apache.hadoop.ipc.ProtobufRpcEngine$Invoker.invoke(ProtobufRpcEngine.java:118)
[2025-03-19T17:37:15.256+0000] {subprocess.py:93} INFO - 	at com.sun.proxy.$Proxy9.addBlock(Unknown Source)
[2025-03-19T17:37:15.257+0000] {subprocess.py:93} INFO - 	at org.apache.hadoop.hdfs.protocolPB.ClientNamenodeProtocolTranslatorPB.addBlock(ClientNamenodeProtocolTranslatorPB.java:517)
[2025-03-19T17:37:15.257+0000] {subprocess.py:93} INFO - 	at sun.reflect.NativeMethodAccessorImpl.invoke0(Native Method)
[2025-03-19T17:37:15.258+0000] {subprocess.py:93} INFO - 	at sun.reflect.NativeMethodAccessorImpl.invoke(NativeMethodAccessorImpl.java:62)
[2025-03-19T17:37:15.258+0000] {subprocess.py:93} INFO - 	at sun.reflect.DelegatingMethodAccessorImpl.invoke(DelegatingMethodAccessorImpl.java:43)
[2025-03-19T17:37:15.259+0000] {subprocess.py:93} INFO - 	at java.lang.reflect.Method.invoke(Method.java:498)
[2025-03-19T17:37:15.259+0000] {subprocess.py:93} INFO - 	at org.apache.hadoop.io.retry.RetryInvocationHandler.invokeMethod(RetryInvocationHandler.java:422)
[2025-03-19T17:37:15.260+0000] {subprocess.py:93} INFO - 	at org.apache.hadoop.io.retry.RetryInvocationHandler$Call.invokeMethod(RetryInvocationHandler.java:165)
[2025-03-19T17:37:15.261+0000] {subprocess.py:93} INFO - 	at org.apache.hadoop.io.retry.RetryInvocationHandler$Call.invoke(RetryInvocationHandler.java:157)
[2025-03-19T17:37:15.263+0000] {subprocess.py:93} INFO - 	at org.apache.hadoop.io.retry.RetryInvocationHandler$Call.invokeOnce(RetryInvocationHandler.java:95)
[2025-03-19T17:37:15.264+0000] {subprocess.py:93} INFO - 	at org.apache.hadoop.io.retry.RetryInvocationHandler.invoke(RetryInvocationHandler.java:359)
[2025-03-19T17:37:15.265+0000] {subprocess.py:93} INFO - 	at com.sun.proxy.$Proxy10.addBlock(Unknown Source)
[2025-03-19T17:37:15.265+0000] {subprocess.py:93} INFO - 	at org.apache.hadoop.hdfs.DFSOutputStream.addBlock(DFSOutputStream.java:1081)
[2025-03-19T17:37:15.266+0000] {subprocess.py:93} INFO - 	... 3 more
[2025-03-19T17:37:15.267+0000] {subprocess.py:93} INFO - put: File does not exist: /data/transactions/transactions.csv._COPYING_ (inode 17589) Holder DFSClient_NONMAPREDUCE_-1183607247_1 does not have any open files.
[2025-03-19T17:37:15.706+0000] {subprocess.py:97} INFO - Command exited with return code 1
[2025-03-19T17:37:15.724+0000] {taskinstance.py:1935} ERROR - Task failed with exception
Traceback (most recent call last):
  File "/home/airflow/.local/lib/python3.8/site-packages/airflow/operators/bash.py", line 210, in execute
    raise AirflowException(
airflow.exceptions.AirflowException: Bash command failed. The command returned a non-zero exit code 1.
[2025-03-19T17:37:15.729+0000] {taskinstance.py:1398} INFO - Marking task as UP_FOR_RETRY. dag_id=faud_detection_pipeline, task_id=store_data_hdfs, execution_date=20231014T020000, start_date=20250319T173659, end_date=20250319T173715
[2025-03-19T17:37:15.757+0000] {standard_task_runner.py:104} ERROR - Failed to execute job 2422 for task store_data_hdfs (Bash command failed. The command returned a non-zero exit code 1.; 35864)
[2025-03-19T17:37:15.807+0000] {local_task_job_runner.py:228} INFO - Task exited with return code 1
[2025-03-19T17:37:15.840+0000] {taskinstance.py:2776} INFO - 0 downstream tasks scheduled from follow-on schedule check
