[2025-03-19T16:45:48.878+0000] {taskinstance.py:1157} INFO - Dependencies all met for dep_context=non-requeueable deps ti=<TaskInstance: faud_detection_pipeline.store_data_hdfs scheduled__2023-10-08T23:00:00+00:00 [queued]>
[2025-03-19T16:45:48.898+0000] {taskinstance.py:1157} INFO - Dependencies all met for dep_context=requeueable deps ti=<TaskInstance: faud_detection_pipeline.store_data_hdfs scheduled__2023-10-08T23:00:00+00:00 [queued]>
[2025-03-19T16:45:48.899+0000] {taskinstance.py:1359} INFO - Starting attempt 1 of 2
[2025-03-19T16:45:48.944+0000] {taskinstance.py:1380} INFO - Executing <Task(BashOperator): store_data_hdfs> on 2023-10-08 23:00:00+00:00
[2025-03-19T16:45:48.952+0000] {standard_task_runner.py:57} INFO - Started process 24890 to run task
[2025-03-19T16:45:48.959+0000] {standard_task_runner.py:84} INFO - Running: ['***', 'tasks', 'run', 'faud_detection_pipeline', 'store_data_hdfs', 'scheduled__2023-10-08T23:00:00+00:00', '--job-id', '1899', '--raw', '--subdir', 'DAGS_FOLDER/dag_1.py', '--cfg-path', '/tmp/tmpawtvx8ou']
[2025-03-19T16:45:48.965+0000] {standard_task_runner.py:85} INFO - Job 1899: Subtask store_data_hdfs
[2025-03-19T16:45:49.080+0000] {task_command.py:415} INFO - Running <TaskInstance: faud_detection_pipeline.store_data_hdfs scheduled__2023-10-08T23:00:00+00:00 [running]> on host 0009f5fb76aa
[2025-03-19T16:45:49.247+0000] {taskinstance.py:1660} INFO - Exporting env vars: AIRFLOW_CTX_DAG_OWNER='***' AIRFLOW_CTX_DAG_ID='faud_detection_pipeline' AIRFLOW_CTX_TASK_ID='store_data_hdfs' AIRFLOW_CTX_EXECUTION_DATE='2023-10-08T23:00:00+00:00' AIRFLOW_CTX_TRY_NUMBER='1' AIRFLOW_CTX_DAG_RUN_ID='scheduled__2023-10-08T23:00:00+00:00'
[2025-03-19T16:45:49.252+0000] {subprocess.py:63} INFO - Tmp dir root location: /tmp
[2025-03-19T16:45:49.255+0000] {subprocess.py:75} INFO - Running command: ['/bin/bash', '-c', 'docker cp /tmp/transactions.csv namenode:/tmp/transactions.csv && docker cp /tmp/customers.csv namenode:/tmp/customers.csv && docker cp /tmp/external_data.csv namenode:/tmp/external_data.csv && docker exec namenode bash -c "hdfs dfs -mkdir -p /data/transactions && hdfs dfs -mkdir -p /data/customers && hdfs dfs -mkdir -p /data/external_data && hdfs dfs -put -f /tmp/transactions.csv /data/transactions/transactions.csv && hdfs dfs -put -f /tmp/customers.csv /data/customers/customers.csv && hdfs dfs -put -f /tmp/external_data.csv /data/external_data/external_data.csv && rm -rf /tmp/transactions.csv /tmp/customers.csv /tmp/external_data.csv"']
[2025-03-19T16:45:49.272+0000] {subprocess.py:86} INFO - Output:
[2025-03-19T16:46:09.595+0000] {subprocess.py:93} INFO - 2025-03-19 16:46:09,592 INFO sasl.SaslDataTransferClient: SASL encryption trust check: localHostTrusted = false, remoteHostTrusted = false
[2025-03-19T16:46:10.139+0000] {subprocess.py:93} INFO - put: rename `/data/transactions/transactions.csv._COPYING_' to `/data/transactions/transactions.csv': Input/output error
[2025-03-19T16:46:08.356+0000] {subprocess.py:97} INFO - Command exited with return code 1
[2025-03-19T16:46:08.391+0000] {taskinstance.py:1935} ERROR - Task failed with exception
Traceback (most recent call last):
  File "/home/airflow/.local/lib/python3.8/site-packages/airflow/operators/bash.py", line 210, in execute
    raise AirflowException(
airflow.exceptions.AirflowException: Bash command failed. The command returned a non-zero exit code 1.
[2025-03-19T16:46:08.407+0000] {taskinstance.py:1398} INFO - Marking task as UP_FOR_RETRY. dag_id=faud_detection_pipeline, task_id=store_data_hdfs, execution_date=20231008T230000, start_date=20250319T164548, end_date=20250319T164608
[2025-03-19T16:46:08.458+0000] {standard_task_runner.py:104} ERROR - Failed to execute job 1899 for task store_data_hdfs (Bash command failed. The command returned a non-zero exit code 1.; 24890)
[2025-03-19T16:46:08.503+0000] {local_task_job_runner.py:228} INFO - Task exited with return code 1
[2025-03-19T16:46:08.571+0000] {taskinstance.py:2776} INFO - 0 downstream tasks scheduled from follow-on schedule check
