[2025-03-19T12:09:46.451+0000] {taskinstance.py:1157} INFO - Dependencies all met for dep_context=non-requeueable deps ti=<TaskInstance: fraud_detection_pipeline.store_data_hdfs scheduled__2023-10-08T03:00:00+00:00 [queued]>
[2025-03-19T12:09:46.484+0000] {taskinstance.py:1157} INFO - Dependencies all met for dep_context=requeueable deps ti=<TaskInstance: fraud_detection_pipeline.store_data_hdfs scheduled__2023-10-08T03:00:00+00:00 [queued]>
[2025-03-19T12:09:46.486+0000] {taskinstance.py:1359} INFO - Starting attempt 1 of 2
[2025-03-19T12:09:46.526+0000] {taskinstance.py:1380} INFO - Executing <Task(BashOperator): store_data_hdfs> on 2023-10-08 03:00:00+00:00
[2025-03-19T12:09:46.539+0000] {standard_task_runner.py:57} INFO - Started process 4158 to run task
[2025-03-19T12:09:46.547+0000] {standard_task_runner.py:84} INFO - Running: ['***', 'tasks', 'run', 'fraud_detection_pipeline', 'store_data_hdfs', 'scheduled__2023-10-08T03:00:00+00:00', '--job-id', '516', '--raw', '--subdir', 'DAGS_FOLDER/dag_1.py', '--cfg-path', '/tmp/tmpi_xxi1ju']
[2025-03-19T12:09:46.554+0000] {standard_task_runner.py:85} INFO - Job 516: Subtask store_data_hdfs
[2025-03-19T12:09:46.686+0000] {task_command.py:415} INFO - Running <TaskInstance: fraud_detection_pipeline.store_data_hdfs scheduled__2023-10-08T03:00:00+00:00 [running]> on host 0009f5fb76aa
[2025-03-19T12:09:47.064+0000] {taskinstance.py:1660} INFO - Exporting env vars: AIRFLOW_CTX_DAG_OWNER='***' AIRFLOW_CTX_DAG_ID='fraud_detection_pipeline' AIRFLOW_CTX_TASK_ID='store_data_hdfs' AIRFLOW_CTX_EXECUTION_DATE='2023-10-08T03:00:00+00:00' AIRFLOW_CTX_TRY_NUMBER='1' AIRFLOW_CTX_DAG_RUN_ID='scheduled__2023-10-08T03:00:00+00:00'
[2025-03-19T12:09:47.069+0000] {subprocess.py:63} INFO - Tmp dir root location: /tmp
[2025-03-19T12:09:47.072+0000] {subprocess.py:75} INFO - Running command: ['/bin/bash', '-c', 'docker cp /tmp/transactions.json namenode:/tmp/transactions.json && docker cp /tmp/customers.json namenode:/tmp/customers.json && docker cp /tmp/external_data.json namenode:/tmp/external_data.json && rm -rf /tmp/external_data.json  && rm -rf /tmp/customers.json  && rm -rf /tmp/transactions.json  && docker exec namenode bash -c "hdfs dfs -mkdir -p /data && hdfs dfs -put -f /tmp/transactions.json /data/transactions.json && hdfs dfs -put -f /tmp/customers.json /data/customers.json && hdfs dfs -put -f /tmp/external_data.json /data/external_data.json && rm -rf /tmp/customers.json  && rm -rf /tmp/customers.json  && rm -rf /tmp/external_data.json "']
[2025-03-19T12:09:47.100+0000] {subprocess.py:86} INFO - Output:
[2025-03-19T12:09:47.198+0000] {subprocess.py:93} INFO - lstat /tmp/transactions.json: no such file or directory
[2025-03-19T12:09:47.203+0000] {subprocess.py:97} INFO - Command exited with return code 1
[2025-03-19T12:09:47.234+0000] {taskinstance.py:1935} ERROR - Task failed with exception
Traceback (most recent call last):
  File "/home/airflow/.local/lib/python3.8/site-packages/airflow/operators/bash.py", line 210, in execute
    raise AirflowException(
airflow.exceptions.AirflowException: Bash command failed. The command returned a non-zero exit code 1.
[2025-03-19T12:09:47.245+0000] {taskinstance.py:1398} INFO - Marking task as UP_FOR_RETRY. dag_id=fraud_detection_pipeline, task_id=store_data_hdfs, execution_date=20231008T030000, start_date=20250319T120946, end_date=20250319T120947
[2025-03-19T12:09:47.329+0000] {standard_task_runner.py:104} ERROR - Failed to execute job 516 for task store_data_hdfs (Bash command failed. The command returned a non-zero exit code 1.; 4158)
[2025-03-19T12:09:47.378+0000] {local_task_job_runner.py:228} INFO - Task exited with return code 1
[2025-03-19T12:09:47.453+0000] {taskinstance.py:2776} INFO - 0 downstream tasks scheduled from follow-on schedule check
