[2025-03-19T21:15:30.137+0000] {taskinstance.py:1157} INFO - Dependencies all met for dep_context=non-requeueable deps ti=<TaskInstance: faud_detection_pipeline.store_data_hdfs scheduled__2023-10-23T15:00:00+00:00 [queued]>
[2025-03-19T21:15:30.341+0000] {taskinstance.py:1157} INFO - Dependencies all met for dep_context=requeueable deps ti=<TaskInstance: faud_detection_pipeline.store_data_hdfs scheduled__2023-10-23T15:00:00+00:00 [queued]>
[2025-03-19T21:15:30.344+0000] {taskinstance.py:1359} INFO - Starting attempt 1 of 1
[2025-03-19T21:15:31.354+0000] {taskinstance.py:1380} INFO - Executing <Task(BashOperator): store_data_hdfs> on 2023-10-23 15:00:00+00:00
[2025-03-19T21:15:31.384+0000] {standard_task_runner.py:57} INFO - Started process 5335 to run task
[2025-03-19T21:15:31.472+0000] {standard_task_runner.py:84} INFO - Running: ['***', 'tasks', 'run', 'faud_detection_pipeline', 'store_data_hdfs', 'scheduled__2023-10-23T15:00:00+00:00', '--job-id', '3193', '--raw', '--subdir', 'DAGS_FOLDER/dag_1.py', '--cfg-path', '/tmp/tmps4a0pu7g']
[2025-03-19T21:15:31.531+0000] {standard_task_runner.py:85} INFO - Job 3193: Subtask store_data_hdfs
[2025-03-19T21:15:31.907+0000] {task_command.py:415} INFO - Running <TaskInstance: faud_detection_pipeline.store_data_hdfs scheduled__2023-10-23T15:00:00+00:00 [running]> on host 445fc0f18383
[2025-03-19T21:15:32.233+0000] {taskinstance.py:1660} INFO - Exporting env vars: AIRFLOW_CTX_DAG_OWNER='***' AIRFLOW_CTX_DAG_ID='faud_detection_pipeline' AIRFLOW_CTX_TASK_ID='store_data_hdfs' AIRFLOW_CTX_EXECUTION_DATE='2023-10-23T15:00:00+00:00' AIRFLOW_CTX_TRY_NUMBER='1' AIRFLOW_CTX_DAG_RUN_ID='scheduled__2023-10-23T15:00:00+00:00'
[2025-03-19T21:15:32.237+0000] {subprocess.py:63} INFO - Tmp dir root location: /tmp
[2025-03-19T21:15:32.240+0000] {subprocess.py:75} INFO - Running command: ['/bin/bash', '-c', 'docker cp /tmp/transactions.csv namenode:/tmp/transactions.csv && docker cp /tmp/customers.csv namenode:/tmp/customers.csv && docker cp /tmp/external_data.csv namenode:/tmp/external_data.csv && docker exec namenode bash -c "hdfs dfs -mkdir -p /data/transactions && hdfs dfs -mkdir -p /data/customers && hdfs dfs -mkdir -p /data/external_data && hdfs dfs -put -f /tmp/transactions.csv /data/transactions/transactions.csv && hdfs dfs -put -f /tmp/customers.csv /data/customers/customers.csv && hdfs dfs -put -f /tmp/external_data.csv /data/external_data/external_data.csv && rm -rf /tmp/transactions.csv /tmp/customers.csv /tmp/external_data.csv"']
[2025-03-19T21:15:32.289+0000] {subprocess.py:86} INFO - Output:
[2025-03-19T21:16:42.078+0000] {subprocess.py:93} INFO - 2025-03-19 21:16:41,926 WARN hdfs.DataStreamer: DataStreamer Exception
[2025-03-19T21:16:42.080+0000] {subprocess.py:93} INFO - java.io.FileNotFoundException: File does not exist: /data/transactions/transactions.csv._COPYING_ (inode 18052) Holder DFSClient_NONMAPREDUCE_-1125314811_1 does not have any open files.
[2025-03-19T21:16:42.081+0000] {subprocess.py:93} INFO - 	at org.apache.hadoop.hdfs.server.namenode.FSNamesystem.checkLease(FSNamesystem.java:2898)
[2025-03-19T21:16:42.081+0000] {subprocess.py:93} INFO - 	at org.apache.hadoop.hdfs.server.namenode.FSDirWriteFileOp.analyzeFileState(FSDirWriteFileOp.java:599)
[2025-03-19T21:16:42.082+0000] {subprocess.py:93} INFO - 	at org.apache.hadoop.hdfs.server.namenode.FSDirWriteFileOp.validateAddBlock(FSDirWriteFileOp.java:171)
[2025-03-19T21:16:42.082+0000] {subprocess.py:93} INFO - 	at org.apache.hadoop.hdfs.server.namenode.FSNamesystem.getAdditionalBlock(FSNamesystem.java:2777)
[2025-03-19T21:16:42.083+0000] {subprocess.py:93} INFO - 	at org.apache.hadoop.hdfs.server.namenode.NameNodeRpcServer.addBlock(NameNodeRpcServer.java:892)
[2025-03-19T21:16:42.084+0000] {subprocess.py:93} INFO - 	at org.apache.hadoop.hdfs.protocolPB.ClientNamenodeProtocolServerSideTranslatorPB.addBlock(ClientNamenodeProtocolServerSideTranslatorPB.java:574)
[2025-03-19T21:16:42.085+0000] {subprocess.py:93} INFO - 	at org.apache.hadoop.hdfs.protocol.proto.ClientNamenodeProtocolProtos$ClientNamenodeProtocol$2.callBlockingMethod(ClientNamenodeProtocolProtos.java)
[2025-03-19T21:16:42.085+0000] {subprocess.py:93} INFO - 	at org.apache.hadoop.ipc.ProtobufRpcEngine$Server$ProtoBufRpcInvoker.call(ProtobufRpcEngine.java:528)
[2025-03-19T21:16:42.086+0000] {subprocess.py:93} INFO - 	at org.apache.hadoop.ipc.RPC$Server.call(RPC.java:1070)
[2025-03-19T21:16:42.086+0000] {subprocess.py:93} INFO - 	at org.apache.hadoop.ipc.Server$RpcCall.run(Server.java:999)
[2025-03-19T21:16:42.087+0000] {subprocess.py:93} INFO - 	at org.apache.hadoop.ipc.Server$RpcCall.run(Server.java:927)
[2025-03-19T21:16:42.087+0000] {subprocess.py:93} INFO - 	at java.security.AccessController.doPrivileged(Native Method)
[2025-03-19T21:16:42.088+0000] {subprocess.py:93} INFO - 	at javax.security.auth.Subject.doAs(Subject.java:422)
[2025-03-19T21:16:42.088+0000] {subprocess.py:93} INFO - 	at org.apache.hadoop.security.UserGroupInformation.doAs(UserGroupInformation.java:1730)
[2025-03-19T21:16:42.089+0000] {subprocess.py:93} INFO - 	at org.apache.hadoop.ipc.Server$Handler.run(Server.java:2915)
[2025-03-19T21:16:42.089+0000] {subprocess.py:93} INFO - 
[2025-03-19T21:16:42.090+0000] {subprocess.py:93} INFO - 	at sun.reflect.NativeConstructorAccessorImpl.newInstance0(Native Method)
[2025-03-19T21:16:42.090+0000] {subprocess.py:93} INFO - 	at sun.reflect.NativeConstructorAccessorImpl.newInstance(NativeConstructorAccessorImpl.java:62)
[2025-03-19T21:16:42.091+0000] {subprocess.py:93} INFO - 	at sun.reflect.DelegatingConstructorAccessorImpl.newInstance(DelegatingConstructorAccessorImpl.java:45)
[2025-03-19T21:16:42.091+0000] {subprocess.py:93} INFO - 	at java.lang.reflect.Constructor.newInstance(Constructor.java:423)
[2025-03-19T21:16:42.092+0000] {subprocess.py:93} INFO - 	at org.apache.hadoop.ipc.RemoteException.instantiateException(RemoteException.java:121)
[2025-03-19T21:16:42.092+0000] {subprocess.py:93} INFO - 	at org.apache.hadoop.ipc.RemoteException.unwrapRemoteException(RemoteException.java:88)
[2025-03-19T21:16:42.093+0000] {subprocess.py:93} INFO - 	at org.apache.hadoop.hdfs.DFSOutputStream.addBlock(DFSOutputStream.java:1084)
[2025-03-19T21:16:42.093+0000] {subprocess.py:93} INFO - 	at org.apache.hadoop.hdfs.DataStreamer.locateFollowingBlock(DataStreamer.java:1866)
[2025-03-19T21:16:42.094+0000] {subprocess.py:93} INFO - 	at org.apache.hadoop.hdfs.DataStreamer.nextBlockOutputStream(DataStreamer.java:1668)
[2025-03-19T21:16:42.094+0000] {subprocess.py:93} INFO - 	at org.apache.hadoop.hdfs.DataStreamer.run(DataStreamer.java:716)
[2025-03-19T21:16:42.095+0000] {subprocess.py:93} INFO - Caused by: org.apache.hadoop.ipc.RemoteException(java.io.FileNotFoundException): File does not exist: /data/transactions/transactions.csv._COPYING_ (inode 18052) Holder DFSClient_NONMAPREDUCE_-1125314811_1 does not have any open files.
[2025-03-19T21:16:42.095+0000] {subprocess.py:93} INFO - 	at org.apache.hadoop.hdfs.server.namenode.FSNamesystem.checkLease(FSNamesystem.java:2898)
[2025-03-19T21:16:42.096+0000] {subprocess.py:93} INFO - 	at org.apache.hadoop.hdfs.server.namenode.FSDirWriteFileOp.analyzeFileState(FSDirWriteFileOp.java:599)
[2025-03-19T21:16:42.097+0000] {subprocess.py:93} INFO - 	at org.apache.hadoop.hdfs.server.namenode.FSDirWriteFileOp.validateAddBlock(FSDirWriteFileOp.java:171)
[2025-03-19T21:16:42.097+0000] {subprocess.py:93} INFO - 	at org.apache.hadoop.hdfs.server.namenode.FSNamesystem.getAdditionalBlock(FSNamesystem.java:2777)
[2025-03-19T21:16:42.098+0000] {subprocess.py:93} INFO - 	at org.apache.hadoop.hdfs.server.namenode.NameNodeRpcServer.addBlock(NameNodeRpcServer.java:892)
[2025-03-19T21:16:42.098+0000] {subprocess.py:93} INFO - 	at org.apache.hadoop.hdfs.protocolPB.ClientNamenodeProtocolServerSideTranslatorPB.addBlock(ClientNamenodeProtocolServerSideTranslatorPB.java:574)
[2025-03-19T21:16:42.099+0000] {subprocess.py:93} INFO - 	at org.apache.hadoop.hdfs.protocol.proto.ClientNamenodeProtocolProtos$ClientNamenodeProtocol$2.callBlockingMethod(ClientNamenodeProtocolProtos.java)
[2025-03-19T21:16:42.103+0000] {subprocess.py:93} INFO - 	at org.apache.hadoop.ipc.ProtobufRpcEngine$Server$ProtoBufRpcInvoker.call(ProtobufRpcEngine.java:528)
[2025-03-19T21:16:42.103+0000] {subprocess.py:93} INFO - 	at org.apache.hadoop.ipc.RPC$Server.call(RPC.java:1070)
[2025-03-19T21:16:42.104+0000] {subprocess.py:93} INFO - 	at org.apache.hadoop.ipc.Server$RpcCall.run(Server.java:999)
[2025-03-19T21:16:42.104+0000] {subprocess.py:93} INFO - 	at org.apache.hadoop.ipc.Server$RpcCall.run(Server.java:927)
[2025-03-19T21:16:42.105+0000] {subprocess.py:93} INFO - 	at java.security.AccessController.doPrivileged(Native Method)
[2025-03-19T21:16:42.106+0000] {subprocess.py:93} INFO - 	at javax.security.auth.Subject.doAs(Subject.java:422)
[2025-03-19T21:16:42.106+0000] {subprocess.py:93} INFO - 	at org.apache.hadoop.security.UserGroupInformation.doAs(UserGroupInformation.java:1730)
[2025-03-19T21:16:42.107+0000] {subprocess.py:93} INFO - 	at org.apache.hadoop.ipc.Server$Handler.run(Server.java:2915)
[2025-03-19T21:16:42.107+0000] {subprocess.py:93} INFO - 
[2025-03-19T21:16:42.108+0000] {subprocess.py:93} INFO - 	at org.apache.hadoop.ipc.Client.getRpcResponse(Client.java:1545)
[2025-03-19T21:16:42.109+0000] {subprocess.py:93} INFO - 	at org.apache.hadoop.ipc.Client.call(Client.java:1491)
[2025-03-19T21:16:42.109+0000] {subprocess.py:93} INFO - 	at org.apache.hadoop.ipc.Client.call(Client.java:1388)
[2025-03-19T21:16:42.110+0000] {subprocess.py:93} INFO - 	at org.apache.hadoop.ipc.ProtobufRpcEngine$Invoker.invoke(ProtobufRpcEngine.java:233)
[2025-03-19T21:16:42.110+0000] {subprocess.py:93} INFO - 	at org.apache.hadoop.ipc.ProtobufRpcEngine$Invoker.invoke(ProtobufRpcEngine.java:118)
[2025-03-19T21:16:42.111+0000] {subprocess.py:93} INFO - 	at com.sun.proxy.$Proxy9.addBlock(Unknown Source)
[2025-03-19T21:16:42.111+0000] {subprocess.py:93} INFO - 	at org.apache.hadoop.hdfs.protocolPB.ClientNamenodeProtocolTranslatorPB.addBlock(ClientNamenodeProtocolTranslatorPB.java:517)
[2025-03-19T21:16:42.112+0000] {subprocess.py:93} INFO - 	at sun.reflect.NativeMethodAccessorImpl.invoke0(Native Method)
[2025-03-19T21:16:42.112+0000] {subprocess.py:93} INFO - 	at sun.reflect.NativeMethodAccessorImpl.invoke(NativeMethodAccessorImpl.java:62)
[2025-03-19T21:16:42.113+0000] {subprocess.py:93} INFO - 	at sun.reflect.DelegatingMethodAccessorImpl.invoke(DelegatingMethodAccessorImpl.java:43)
[2025-03-19T21:16:42.113+0000] {subprocess.py:93} INFO - 	at java.lang.reflect.Method.invoke(Method.java:498)
[2025-03-19T21:16:42.114+0000] {subprocess.py:93} INFO - 	at org.apache.hadoop.io.retry.RetryInvocationHandler.invokeMethod(RetryInvocationHandler.java:422)
[2025-03-19T21:16:42.115+0000] {subprocess.py:93} INFO - 	at org.apache.hadoop.io.retry.RetryInvocationHandler$Call.invokeMethod(RetryInvocationHandler.java:165)
[2025-03-19T21:16:42.115+0000] {subprocess.py:93} INFO - 	at org.apache.hadoop.io.retry.RetryInvocationHandler$Call.invoke(RetryInvocationHandler.java:157)
[2025-03-19T21:16:42.116+0000] {subprocess.py:93} INFO - 	at org.apache.hadoop.io.retry.RetryInvocationHandler$Call.invokeOnce(RetryInvocationHandler.java:95)
[2025-03-19T21:16:42.118+0000] {subprocess.py:93} INFO - 	at org.apache.hadoop.io.retry.RetryInvocationHandler.invoke(RetryInvocationHandler.java:359)
[2025-03-19T21:16:42.120+0000] {subprocess.py:93} INFO - 	at com.sun.proxy.$Proxy10.addBlock(Unknown Source)
[2025-03-19T21:16:42.120+0000] {subprocess.py:93} INFO - 	at org.apache.hadoop.hdfs.DFSOutputStream.addBlock(DFSOutputStream.java:1081)
[2025-03-19T21:16:42.121+0000] {subprocess.py:93} INFO - 	... 3 more
[2025-03-19T21:16:42.121+0000] {subprocess.py:93} INFO - put: File does not exist: /data/transactions/transactions.csv._COPYING_ (inode 18052) Holder DFSClient_NONMAPREDUCE_-1125314811_1 does not have any open files.
[2025-03-19T21:16:42.650+0000] {subprocess.py:97} INFO - Command exited with return code 1
[2025-03-19T21:16:42.678+0000] {taskinstance.py:1935} ERROR - Task failed with exception
Traceback (most recent call last):
  File "/home/airflow/.local/lib/python3.8/site-packages/airflow/operators/bash.py", line 210, in execute
    raise AirflowException(
airflow.exceptions.AirflowException: Bash command failed. The command returned a non-zero exit code 1.
[2025-03-19T21:16:42.696+0000] {taskinstance.py:1398} INFO - Marking task as FAILED. dag_id=faud_detection_pipeline, task_id=store_data_hdfs, execution_date=20231023T150000, start_date=20250319T211530, end_date=20250319T211642
[2025-03-19T21:16:42.965+0000] {standard_task_runner.py:104} ERROR - Failed to execute job 3193 for task store_data_hdfs (Bash command failed. The command returned a non-zero exit code 1.; 5335)
[2025-03-19T21:16:43.016+0000] {local_task_job_runner.py:228} INFO - Task exited with return code 1
[2025-03-19T21:16:43.090+0000] {taskinstance.py:2776} INFO - 0 downstream tasks scheduled from follow-on schedule check
