[2025-03-19T17:06:54.428+0000] {taskinstance.py:1157} INFO - Dependencies all met for dep_context=non-requeueable deps ti=<TaskInstance: faud_detection_pipeline.run_fraud_detection scheduled__2023-10-10T11:00:00+00:00 [queued]>
[2025-03-19T17:06:54.443+0000] {taskinstance.py:1157} INFO - Dependencies all met for dep_context=requeueable deps ti=<TaskInstance: faud_detection_pipeline.run_fraud_detection scheduled__2023-10-10T11:00:00+00:00 [queued]>
[2025-03-19T17:06:54.445+0000] {taskinstance.py:1359} INFO - Starting attempt 2 of 2
[2025-03-19T17:06:54.476+0000] {taskinstance.py:1380} INFO - Executing <Task(PythonOperator): run_fraud_detection> on 2023-10-10 11:00:00+00:00
[2025-03-19T17:06:54.486+0000] {standard_task_runner.py:57} INFO - Started process 29527 to run task
[2025-03-19T17:06:54.492+0000] {standard_task_runner.py:84} INFO - Running: ['***', 'tasks', 'run', 'faud_detection_pipeline', 'run_fraud_detection', 'scheduled__2023-10-10T11:00:00+00:00', '--job-id', '2122', '--raw', '--subdir', 'DAGS_FOLDER/dag_1.py', '--cfg-path', '/tmp/tmp_dk6j7py']
[2025-03-19T17:06:54.497+0000] {standard_task_runner.py:85} INFO - Job 2122: Subtask run_fraud_detection
[2025-03-19T17:06:54.588+0000] {task_command.py:415} INFO - Running <TaskInstance: faud_detection_pipeline.run_fraud_detection scheduled__2023-10-10T11:00:00+00:00 [running]> on host 0009f5fb76aa
[2025-03-19T17:06:54.773+0000] {taskinstance.py:1660} INFO - Exporting env vars: AIRFLOW_CTX_DAG_OWNER='***' AIRFLOW_CTX_DAG_ID='faud_detection_pipeline' AIRFLOW_CTX_TASK_ID='run_fraud_detection' AIRFLOW_CTX_EXECUTION_DATE='2023-10-10T11:00:00+00:00' AIRFLOW_CTX_TRY_NUMBER='2' AIRFLOW_CTX_DAG_RUN_ID='scheduled__2023-10-10T11:00:00+00:00'
[2025-03-19T17:06:54.800+0000] {taskinstance.py:1935} ERROR - Task failed with exception
Traceback (most recent call last):
  File "/home/airflow/.local/lib/python3.8/site-packages/airflow/operators/python.py", line 192, in execute
    return_value = self.execute_callable()
  File "/home/airflow/.local/lib/python3.8/site-packages/airflow/operators/python.py", line 209, in execute_callable
    return self.python_callable(*self.op_args, **self.op_kwargs)
  File "/opt/airflow/dags/dag_1.py", line 124, in run_fraud_detection
    subprocess.run(["hive", "-e", query])
  File "/usr/local/lib/python3.8/subprocess.py", line 493, in run
    with Popen(*popenargs, **kwargs) as process:
  File "/usr/local/lib/python3.8/subprocess.py", line 858, in __init__
    self._execute_child(args, executable, preexec_fn, close_fds,
  File "/usr/local/lib/python3.8/subprocess.py", line 1720, in _execute_child
    raise child_exception_type(errno_num, err_msg, err_filename)
PermissionError: [Errno 13] Permission denied: 'hive'
[2025-03-19T17:06:54.821+0000] {taskinstance.py:1398} INFO - Marking task as FAILED. dag_id=faud_detection_pipeline, task_id=run_fraud_detection, execution_date=20231010T110000, start_date=20250319T170654, end_date=20250319T170654
[2025-03-19T17:06:54.844+0000] {standard_task_runner.py:104} ERROR - Failed to execute job 2122 for task run_fraud_detection ([Errno 13] Permission denied: 'hive'; 29527)
[2025-03-19T17:06:54.871+0000] {local_task_job_runner.py:228} INFO - Task exited with return code 1
[2025-03-19T17:06:54.917+0000] {taskinstance.py:2776} INFO - 0 downstream tasks scheduled from follow-on schedule check
