[2025-03-19T17:37:18.868+0000] {taskinstance.py:1157} INFO - Dependencies all met for dep_context=non-requeueable deps ti=<TaskInstance: faud_detection_pipeline.store_data_hdfs scheduled__2023-10-13T14:00:00+00:00 [queued]>
[2025-03-19T17:37:18.898+0000] {taskinstance.py:1157} INFO - Dependencies all met for dep_context=requeueable deps ti=<TaskInstance: faud_detection_pipeline.store_data_hdfs scheduled__2023-10-13T14:00:00+00:00 [queued]>
[2025-03-19T17:37:18.899+0000] {taskinstance.py:1359} INFO - Starting attempt 2 of 2
[2025-03-19T17:37:18.949+0000] {taskinstance.py:1380} INFO - Executing <Task(BashOperator): store_data_hdfs> on 2023-10-13 14:00:00+00:00
[2025-03-19T17:37:18.961+0000] {standard_task_runner.py:57} INFO - Started process 35987 to run task
[2025-03-19T17:37:18.968+0000] {standard_task_runner.py:84} INFO - Running: ['***', 'tasks', 'run', 'faud_detection_pipeline', 'store_data_hdfs', 'scheduled__2023-10-13T14:00:00+00:00', '--job-id', '2425', '--raw', '--subdir', 'DAGS_FOLDER/dag_1.py', '--cfg-path', '/tmp/tmpekqzpvtf']
[2025-03-19T17:37:18.977+0000] {standard_task_runner.py:85} INFO - Job 2425: Subtask store_data_hdfs
[2025-03-19T17:37:19.251+0000] {task_command.py:415} INFO - Running <TaskInstance: faud_detection_pipeline.store_data_hdfs scheduled__2023-10-13T14:00:00+00:00 [running]> on host 0009f5fb76aa
[2025-03-19T17:37:19.443+0000] {taskinstance.py:1660} INFO - Exporting env vars: AIRFLOW_CTX_DAG_OWNER='***' AIRFLOW_CTX_DAG_ID='faud_detection_pipeline' AIRFLOW_CTX_TASK_ID='store_data_hdfs' AIRFLOW_CTX_EXECUTION_DATE='2023-10-13T14:00:00+00:00' AIRFLOW_CTX_TRY_NUMBER='2' AIRFLOW_CTX_DAG_RUN_ID='scheduled__2023-10-13T14:00:00+00:00'
[2025-03-19T17:37:19.446+0000] {subprocess.py:63} INFO - Tmp dir root location: /tmp
[2025-03-19T17:37:19.448+0000] {subprocess.py:75} INFO - Running command: ['/bin/bash', '-c', 'docker cp /tmp/transactions.csv namenode:/tmp/transactions.csv && docker cp /tmp/customers.csv namenode:/tmp/customers.csv && docker cp /tmp/external_data.csv namenode:/tmp/external_data.csv && docker exec namenode bash -c "hdfs dfs -mkdir -p /data/transactions && hdfs dfs -mkdir -p /data/customers && hdfs dfs -mkdir -p /data/external_data && hdfs dfs -put -f /tmp/transactions.csv /data/transactions/transactions.csv && hdfs dfs -put -f /tmp/customers.csv /data/customers/customers.csv && hdfs dfs -put -f /tmp/external_data.csv /data/external_data/external_data.csv && rm -rf /tmp/transactions.csv /tmp/customers.csv /tmp/external_data.csv"']
[2025-03-19T17:37:19.466+0000] {subprocess.py:86} INFO - Output:
[2025-03-19T17:37:36.581+0000] {subprocess.py:93} INFO - 2025-03-19 17:37:36,571 WARN hdfs.DataStreamer: DataStreamer Exception
[2025-03-19T17:37:36.582+0000] {subprocess.py:93} INFO - java.io.FileNotFoundException: File does not exist: /data/transactions/transactions.csv._COPYING_ (inode 17591) Holder DFSClient_NONMAPREDUCE_863696772_1 does not have any open files.
[2025-03-19T17:37:36.583+0000] {subprocess.py:93} INFO - 	at org.apache.hadoop.hdfs.server.namenode.FSNamesystem.checkLease(FSNamesystem.java:2898)
[2025-03-19T17:37:36.584+0000] {subprocess.py:93} INFO - 	at org.apache.hadoop.hdfs.server.namenode.FSDirWriteFileOp.analyzeFileState(FSDirWriteFileOp.java:599)
[2025-03-19T17:37:36.585+0000] {subprocess.py:93} INFO - 	at org.apache.hadoop.hdfs.server.namenode.FSDirWriteFileOp.validateAddBlock(FSDirWriteFileOp.java:171)
[2025-03-19T17:37:36.585+0000] {subprocess.py:93} INFO - 	at org.apache.hadoop.hdfs.server.namenode.FSNamesystem.getAdditionalBlock(FSNamesystem.java:2777)
[2025-03-19T17:37:36.586+0000] {subprocess.py:93} INFO - 	at org.apache.hadoop.hdfs.server.namenode.NameNodeRpcServer.addBlock(NameNodeRpcServer.java:892)
[2025-03-19T17:37:36.587+0000] {subprocess.py:93} INFO - 	at org.apache.hadoop.hdfs.protocolPB.ClientNamenodeProtocolServerSideTranslatorPB.addBlock(ClientNamenodeProtocolServerSideTranslatorPB.java:574)
[2025-03-19T17:37:36.587+0000] {subprocess.py:93} INFO - 	at org.apache.hadoop.hdfs.protocol.proto.ClientNamenodeProtocolProtos$ClientNamenodeProtocol$2.callBlockingMethod(ClientNamenodeProtocolProtos.java)
[2025-03-19T17:37:36.588+0000] {subprocess.py:93} INFO - 	at org.apache.hadoop.ipc.ProtobufRpcEngine$Server$ProtoBufRpcInvoker.call(ProtobufRpcEngine.java:528)
[2025-03-19T17:37:36.589+0000] {subprocess.py:93} INFO - 	at org.apache.hadoop.ipc.RPC$Server.call(RPC.java:1070)
[2025-03-19T17:37:36.590+0000] {subprocess.py:93} INFO - 	at org.apache.hadoop.ipc.Server$RpcCall.run(Server.java:999)
[2025-03-19T17:37:36.591+0000] {subprocess.py:93} INFO - 	at org.apache.hadoop.ipc.Server$RpcCall.run(Server.java:927)
[2025-03-19T17:37:36.593+0000] {subprocess.py:93} INFO - 	at java.security.AccessController.doPrivileged(Native Method)
[2025-03-19T17:37:36.594+0000] {subprocess.py:93} INFO - 	at javax.security.auth.Subject.doAs(Subject.java:422)
[2025-03-19T17:37:36.595+0000] {subprocess.py:93} INFO - 	at org.apache.hadoop.security.UserGroupInformation.doAs(UserGroupInformation.java:1730)
[2025-03-19T17:37:36.598+0000] {subprocess.py:93} INFO - 	at org.apache.hadoop.ipc.Server$Handler.run(Server.java:2915)
[2025-03-19T17:37:36.600+0000] {subprocess.py:93} INFO - 
[2025-03-19T17:37:36.602+0000] {subprocess.py:93} INFO - 	at sun.reflect.NativeConstructorAccessorImpl.newInstance0(Native Method)
[2025-03-19T17:37:36.604+0000] {subprocess.py:93} INFO - 	at sun.reflect.NativeConstructorAccessorImpl.newInstance(NativeConstructorAccessorImpl.java:62)
[2025-03-19T17:37:36.605+0000] {subprocess.py:93} INFO - 	at sun.reflect.DelegatingConstructorAccessorImpl.newInstance(DelegatingConstructorAccessorImpl.java:45)
[2025-03-19T17:37:36.606+0000] {subprocess.py:93} INFO - 	at java.lang.reflect.Constructor.newInstance(Constructor.java:423)
[2025-03-19T17:37:36.607+0000] {subprocess.py:93} INFO - 	at org.apache.hadoop.ipc.RemoteException.instantiateException(RemoteException.java:121)
[2025-03-19T17:37:36.608+0000] {subprocess.py:93} INFO - 	at org.apache.hadoop.ipc.RemoteException.unwrapRemoteException(RemoteException.java:88)
[2025-03-19T17:37:36.609+0000] {subprocess.py:93} INFO - 	at org.apache.hadoop.hdfs.DFSOutputStream.addBlock(DFSOutputStream.java:1084)
[2025-03-19T17:37:36.609+0000] {subprocess.py:93} INFO - 	at org.apache.hadoop.hdfs.DataStreamer.locateFollowingBlock(DataStreamer.java:1866)
[2025-03-19T17:37:36.610+0000] {subprocess.py:93} INFO - 	at org.apache.hadoop.hdfs.DataStreamer.nextBlockOutputStream(DataStreamer.java:1668)
[2025-03-19T17:37:36.611+0000] {subprocess.py:93} INFO - 	at org.apache.hadoop.hdfs.DataStreamer.run(DataStreamer.java:716)
[2025-03-19T17:37:36.614+0000] {subprocess.py:93} INFO - Caused by: org.apache.hadoop.ipc.RemoteException(java.io.FileNotFoundException): File does not exist: /data/transactions/transactions.csv._COPYING_ (inode 17591) Holder DFSClient_NONMAPREDUCE_863696772_1 does not have any open files.
[2025-03-19T17:37:36.615+0000] {subprocess.py:93} INFO - 	at org.apache.hadoop.hdfs.server.namenode.FSNamesystem.checkLease(FSNamesystem.java:2898)
[2025-03-19T17:37:36.617+0000] {subprocess.py:93} INFO - 	at org.apache.hadoop.hdfs.server.namenode.FSDirWriteFileOp.analyzeFileState(FSDirWriteFileOp.java:599)
[2025-03-19T17:37:36.618+0000] {subprocess.py:93} INFO - 	at org.apache.hadoop.hdfs.server.namenode.FSDirWriteFileOp.validateAddBlock(FSDirWriteFileOp.java:171)
[2025-03-19T17:37:36.619+0000] {subprocess.py:93} INFO - 	at org.apache.hadoop.hdfs.server.namenode.FSNamesystem.getAdditionalBlock(FSNamesystem.java:2777)
[2025-03-19T17:37:36.621+0000] {subprocess.py:93} INFO - 	at org.apache.hadoop.hdfs.server.namenode.NameNodeRpcServer.addBlock(NameNodeRpcServer.java:892)
[2025-03-19T17:37:36.628+0000] {subprocess.py:93} INFO - 	at org.apache.hadoop.hdfs.protocolPB.ClientNamenodeProtocolServerSideTranslatorPB.addBlock(ClientNamenodeProtocolServerSideTranslatorPB.java:574)
[2025-03-19T17:37:36.629+0000] {subprocess.py:93} INFO - 	at org.apache.hadoop.hdfs.protocol.proto.ClientNamenodeProtocolProtos$ClientNamenodeProtocol$2.callBlockingMethod(ClientNamenodeProtocolProtos.java)
[2025-03-19T17:37:36.630+0000] {subprocess.py:93} INFO - 	at org.apache.hadoop.ipc.ProtobufRpcEngine$Server$ProtoBufRpcInvoker.call(ProtobufRpcEngine.java:528)
[2025-03-19T17:37:36.631+0000] {subprocess.py:93} INFO - 	at org.apache.hadoop.ipc.RPC$Server.call(RPC.java:1070)
[2025-03-19T17:37:36.632+0000] {subprocess.py:93} INFO - 	at org.apache.hadoop.ipc.Server$RpcCall.run(Server.java:999)
[2025-03-19T17:37:36.633+0000] {subprocess.py:93} INFO - 	at org.apache.hadoop.ipc.Server$RpcCall.run(Server.java:927)
[2025-03-19T17:37:36.634+0000] {subprocess.py:93} INFO - 	at java.security.AccessController.doPrivileged(Native Method)
[2025-03-19T17:37:36.639+0000] {subprocess.py:93} INFO - 	at javax.security.auth.Subject.doAs(Subject.java:422)
[2025-03-19T17:37:36.640+0000] {subprocess.py:93} INFO - 	at org.apache.hadoop.security.UserGroupInformation.doAs(UserGroupInformation.java:1730)
[2025-03-19T17:37:36.643+0000] {subprocess.py:93} INFO - 	at org.apache.hadoop.ipc.Server$Handler.run(Server.java:2915)
[2025-03-19T17:37:36.644+0000] {subprocess.py:93} INFO - 
[2025-03-19T17:37:36.649+0000] {subprocess.py:93} INFO - 	at org.apache.hadoop.ipc.Client.getRpcResponse(Client.java:1545)
[2025-03-19T17:37:36.652+0000] {subprocess.py:93} INFO - 	at org.apache.hadoop.ipc.Client.call(Client.java:1491)
[2025-03-19T17:37:36.653+0000] {subprocess.py:93} INFO - 	at org.apache.hadoop.ipc.Client.call(Client.java:1388)
[2025-03-19T17:37:36.654+0000] {subprocess.py:93} INFO - 	at org.apache.hadoop.ipc.ProtobufRpcEngine$Invoker.invoke(ProtobufRpcEngine.java:233)
[2025-03-19T17:37:36.655+0000] {subprocess.py:93} INFO - 	at org.apache.hadoop.ipc.ProtobufRpcEngine$Invoker.invoke(ProtobufRpcEngine.java:118)
[2025-03-19T17:37:36.657+0000] {subprocess.py:93} INFO - 	at com.sun.proxy.$Proxy9.addBlock(Unknown Source)
[2025-03-19T17:37:36.658+0000] {subprocess.py:93} INFO - 	at org.apache.hadoop.hdfs.protocolPB.ClientNamenodeProtocolTranslatorPB.addBlock(ClientNamenodeProtocolTranslatorPB.java:517)
[2025-03-19T17:37:36.659+0000] {subprocess.py:93} INFO - 	at sun.reflect.NativeMethodAccessorImpl.invoke0(Native Method)
[2025-03-19T17:37:36.661+0000] {subprocess.py:93} INFO - 	at sun.reflect.NativeMethodAccessorImpl.invoke(NativeMethodAccessorImpl.java:62)
[2025-03-19T17:37:36.662+0000] {subprocess.py:93} INFO - 	at sun.reflect.DelegatingMethodAccessorImpl.invoke(DelegatingMethodAccessorImpl.java:43)
[2025-03-19T17:37:36.662+0000] {subprocess.py:93} INFO - 	at java.lang.reflect.Method.invoke(Method.java:498)
[2025-03-19T17:37:36.675+0000] {subprocess.py:93} INFO - 	at org.apache.hadoop.io.retry.RetryInvocationHandler.invokeMethod(RetryInvocationHandler.java:422)
[2025-03-19T17:37:36.676+0000] {subprocess.py:93} INFO - 	at org.apache.hadoop.io.retry.RetryInvocationHandler$Call.invokeMethod(RetryInvocationHandler.java:165)
[2025-03-19T17:37:36.678+0000] {subprocess.py:93} INFO - 	at org.apache.hadoop.io.retry.RetryInvocationHandler$Call.invoke(RetryInvocationHandler.java:157)
[2025-03-19T17:37:36.679+0000] {subprocess.py:93} INFO - 	at org.apache.hadoop.io.retry.RetryInvocationHandler$Call.invokeOnce(RetryInvocationHandler.java:95)
[2025-03-19T17:37:36.682+0000] {subprocess.py:93} INFO - 	at org.apache.hadoop.io.retry.RetryInvocationHandler.invoke(RetryInvocationHandler.java:359)
[2025-03-19T17:37:36.682+0000] {subprocess.py:93} INFO - 	at com.sun.proxy.$Proxy10.addBlock(Unknown Source)
[2025-03-19T17:37:36.683+0000] {subprocess.py:93} INFO - 	at org.apache.hadoop.hdfs.DFSOutputStream.addBlock(DFSOutputStream.java:1081)
[2025-03-19T17:37:36.684+0000] {subprocess.py:93} INFO - 	... 3 more
[2025-03-19T17:37:36.685+0000] {subprocess.py:93} INFO - put: File does not exist: /data/transactions/transactions.csv._COPYING_ (inode 17591) Holder DFSClient_NONMAPREDUCE_863696772_1 does not have any open files.
[2025-03-19T17:37:37.036+0000] {subprocess.py:97} INFO - Command exited with return code 1
[2025-03-19T17:37:37.053+0000] {taskinstance.py:1935} ERROR - Task failed with exception
Traceback (most recent call last):
  File "/home/airflow/.local/lib/python3.8/site-packages/airflow/operators/bash.py", line 210, in execute
    raise AirflowException(
airflow.exceptions.AirflowException: Bash command failed. The command returned a non-zero exit code 1.
[2025-03-19T17:37:37.059+0000] {taskinstance.py:1398} INFO - Marking task as FAILED. dag_id=faud_detection_pipeline, task_id=store_data_hdfs, execution_date=20231013T140000, start_date=20250319T173718, end_date=20250319T173737
[2025-03-19T17:37:37.086+0000] {standard_task_runner.py:104} ERROR - Failed to execute job 2425 for task store_data_hdfs (Bash command failed. The command returned a non-zero exit code 1.; 35987)
[2025-03-19T17:37:37.116+0000] {local_task_job_runner.py:228} INFO - Task exited with return code 1
[2025-03-19T17:37:37.186+0000] {taskinstance.py:2776} INFO - 0 downstream tasks scheduled from follow-on schedule check
