[2025-03-19T19:17:56.389+0000] {taskinstance.py:1157} INFO - Dependencies all met for dep_context=non-requeueable deps ti=<TaskInstance: faud_detection_pipeline.store_data_hdfs scheduled__2023-10-14T21:00:00+00:00 [queued]>
[2025-03-19T19:17:56.479+0000] {taskinstance.py:1157} INFO - Dependencies all met for dep_context=requeueable deps ti=<TaskInstance: faud_detection_pipeline.store_data_hdfs scheduled__2023-10-14T21:00:00+00:00 [queued]>
[2025-03-19T19:17:56.490+0000] {taskinstance.py:1359} INFO - Starting attempt 2 of 2
[2025-03-19T19:17:56.577+0000] {taskinstance.py:1380} INFO - Executing <Task(BashOperator): store_data_hdfs> on 2023-10-14 21:00:00+00:00
[2025-03-19T19:17:56.652+0000] {standard_task_runner.py:57} INFO - Started process 38174 to run task
[2025-03-19T19:17:56.663+0000] {standard_task_runner.py:84} INFO - Running: ['***', 'tasks', 'run', 'faud_detection_pipeline', 'store_data_hdfs', 'scheduled__2023-10-14T21:00:00+00:00', '--job-id', '2516', '--raw', '--subdir', 'DAGS_FOLDER/dag_1.py', '--cfg-path', '/tmp/tmp3aqla0dg']
[2025-03-19T19:17:56.677+0000] {standard_task_runner.py:85} INFO - Job 2516: Subtask store_data_hdfs
[2025-03-19T19:17:57.123+0000] {task_command.py:415} INFO - Running <TaskInstance: faud_detection_pipeline.store_data_hdfs scheduled__2023-10-14T21:00:00+00:00 [running]> on host 0009f5fb76aa
[2025-03-19T19:17:57.562+0000] {taskinstance.py:1660} INFO - Exporting env vars: AIRFLOW_CTX_DAG_OWNER='***' AIRFLOW_CTX_DAG_ID='faud_detection_pipeline' AIRFLOW_CTX_TASK_ID='store_data_hdfs' AIRFLOW_CTX_EXECUTION_DATE='2023-10-14T21:00:00+00:00' AIRFLOW_CTX_TRY_NUMBER='2' AIRFLOW_CTX_DAG_RUN_ID='scheduled__2023-10-14T21:00:00+00:00'
[2025-03-19T19:17:57.578+0000] {subprocess.py:63} INFO - Tmp dir root location: /tmp
[2025-03-19T19:17:57.581+0000] {subprocess.py:75} INFO - Running command: ['/bin/bash', '-c', 'docker cp /tmp/transactions.csv namenode:/tmp/transactions.csv && docker cp /tmp/customers.csv namenode:/tmp/customers.csv && docker cp /tmp/external_data.csv namenode:/tmp/external_data.csv && docker exec namenode bash -c "hdfs dfs -mkdir -p /data/transactions && hdfs dfs -mkdir -p /data/customers && hdfs dfs -mkdir -p /data/external_data && hdfs dfs -put -f /tmp/transactions.csv /data/transactions/transactions.csv && hdfs dfs -put -f /tmp/customers.csv /data/customers/customers.csv && hdfs dfs -put -f /tmp/external_data.csv /data/external_data/external_data.csv && rm -rf /tmp/transactions.csv /tmp/customers.csv /tmp/external_data.csv"']
[2025-03-19T19:17:57.782+0000] {subprocess.py:86} INFO - Output:
[2025-03-19T19:18:54.467+0000] {subprocess.py:93} INFO - 2025-03-19 19:18:54,465 INFO sasl.SaslDataTransferClient: SASL encryption trust check: localHostTrusted = false, remoteHostTrusted = false
[2025-03-19T19:18:54.919+0000] {subprocess.py:93} INFO - put: File does not exist: /data/transactions/transactions.csv._COPYING_ (inode 17647) Holder DFSClient_NONMAPREDUCE_1299766220_1 does not have any open files.
[2025-03-19T19:18:55.341+0000] {subprocess.py:97} INFO - Command exited with return code 1
[2025-03-19T19:18:55.370+0000] {taskinstance.py:1935} ERROR - Task failed with exception
Traceback (most recent call last):
  File "/home/airflow/.local/lib/python3.8/site-packages/airflow/operators/bash.py", line 210, in execute
    raise AirflowException(
airflow.exceptions.AirflowException: Bash command failed. The command returned a non-zero exit code 1.
[2025-03-19T19:18:55.376+0000] {taskinstance.py:1398} INFO - Marking task as FAILED. dag_id=faud_detection_pipeline, task_id=store_data_hdfs, execution_date=20231014T210000, start_date=20250319T191756, end_date=20250319T191855
[2025-03-19T19:18:55.412+0000] {standard_task_runner.py:104} ERROR - Failed to execute job 2516 for task store_data_hdfs (Bash command failed. The command returned a non-zero exit code 1.; 38174)
[2025-03-19T19:18:55.460+0000] {local_task_job_runner.py:228} INFO - Task exited with return code 1
[2025-03-19T19:18:55.508+0000] {taskinstance.py:2776} INFO - 0 downstream tasks scheduled from follow-on schedule check
