[2025-03-19T11:32:02.217+0000] {taskinstance.py:1157} INFO - Dependencies all met for dep_context=non-requeueable deps ti=<TaskInstance: fraud_detection_pipeline.store_data_hdfs scheduled__2023-10-03T20:00:00+00:00 [queued]>
[2025-03-19T11:32:02.285+0000] {taskinstance.py:1157} INFO - Dependencies all met for dep_context=requeueable deps ti=<TaskInstance: fraud_detection_pipeline.store_data_hdfs scheduled__2023-10-03T20:00:00+00:00 [queued]>
[2025-03-19T11:32:02.286+0000] {taskinstance.py:1359} INFO - Starting attempt 1 of 2
[2025-03-19T11:32:02.350+0000] {taskinstance.py:1380} INFO - Executing <Task(BashOperator): store_data_hdfs> on 2023-10-03 20:00:00+00:00
[2025-03-19T11:32:02.362+0000] {standard_task_runner.py:57} INFO - Started process 5480 to run task
[2025-03-19T11:32:02.382+0000] {standard_task_runner.py:84} INFO - Running: ['***', 'tasks', 'run', 'fraud_detection_pipeline', 'store_data_hdfs', 'scheduled__2023-10-03T20:00:00+00:00', '--job-id', '184', '--raw', '--subdir', 'DAGS_FOLDER/dag_1.py', '--cfg-path', '/tmp/tmp323re3a2']
[2025-03-19T11:32:02.389+0000] {standard_task_runner.py:85} INFO - Job 184: Subtask store_data_hdfs
[2025-03-19T11:32:02.534+0000] {task_command.py:415} INFO - Running <TaskInstance: fraud_detection_pipeline.store_data_hdfs scheduled__2023-10-03T20:00:00+00:00 [running]> on host 0009f5fb76aa
[2025-03-19T11:32:02.767+0000] {taskinstance.py:1660} INFO - Exporting env vars: AIRFLOW_CTX_DAG_OWNER='***' AIRFLOW_CTX_DAG_ID='fraud_detection_pipeline' AIRFLOW_CTX_TASK_ID='store_data_hdfs' AIRFLOW_CTX_EXECUTION_DATE='2023-10-03T20:00:00+00:00' AIRFLOW_CTX_TRY_NUMBER='1' AIRFLOW_CTX_DAG_RUN_ID='scheduled__2023-10-03T20:00:00+00:00'
[2025-03-19T11:32:02.773+0000] {subprocess.py:63} INFO - Tmp dir root location: /tmp
[2025-03-19T11:32:02.776+0000] {subprocess.py:75} INFO - Running command: ['/bin/bash', '-c', 'hdfs dfs -put /tmp/transactions.json /data/transactions.json && hdfs dfs -put /tmp/customers.json /data/customers.json && hdfs dfs -put /tmp/external_data.json /data/external_data.json']
[2025-03-19T11:32:02.805+0000] {subprocess.py:86} INFO - Output:
[2025-03-19T11:32:02.811+0000] {subprocess.py:93} INFO - /bin/bash: line 1: hdfs: command not found
[2025-03-19T11:32:02.812+0000] {subprocess.py:97} INFO - Command exited with return code 127
[2025-03-19T11:32:02.831+0000] {taskinstance.py:1935} ERROR - Task failed with exception
Traceback (most recent call last):
  File "/home/airflow/.local/lib/python3.8/site-packages/airflow/operators/bash.py", line 210, in execute
    raise AirflowException(
airflow.exceptions.AirflowException: Bash command failed. The command returned a non-zero exit code 127.
[2025-03-19T11:32:02.839+0000] {taskinstance.py:1398} INFO - Marking task as UP_FOR_RETRY. dag_id=fraud_detection_pipeline, task_id=store_data_hdfs, execution_date=20231003T200000, start_date=20250319T113202, end_date=20250319T113202
[2025-03-19T11:32:02.868+0000] {standard_task_runner.py:104} ERROR - Failed to execute job 184 for task store_data_hdfs (Bash command failed. The command returned a non-zero exit code 127.; 5480)
[2025-03-19T11:32:02.888+0000] {local_task_job_runner.py:228} INFO - Task exited with return code 1
[2025-03-19T11:32:02.939+0000] {taskinstance.py:2776} INFO - 0 downstream tasks scheduled from follow-on schedule check
