[2025-03-19T17:39:06.444+0000] {taskinstance.py:1157} INFO - Dependencies all met for dep_context=non-requeueable deps ti=<TaskInstance: faud_detection_pipeline.store_data_hdfs scheduled__2023-10-14T08:00:00+00:00 [queued]>
[2025-03-19T17:39:06.488+0000] {taskinstance.py:1157} INFO - Dependencies all met for dep_context=requeueable deps ti=<TaskInstance: faud_detection_pipeline.store_data_hdfs scheduled__2023-10-14T08:00:00+00:00 [queued]>
[2025-03-19T17:39:06.496+0000] {taskinstance.py:1359} INFO - Starting attempt 1 of 2
[2025-03-19T17:39:06.550+0000] {taskinstance.py:1380} INFO - Executing <Task(BashOperator): store_data_hdfs> on 2023-10-14 08:00:00+00:00
[2025-03-19T17:39:06.562+0000] {standard_task_runner.py:57} INFO - Started process 36572 to run task
[2025-03-19T17:39:06.570+0000] {standard_task_runner.py:84} INFO - Running: ['***', 'tasks', 'run', 'faud_detection_pipeline', 'store_data_hdfs', 'scheduled__2023-10-14T08:00:00+00:00', '--job-id', '2451', '--raw', '--subdir', 'DAGS_FOLDER/dag_1.py', '--cfg-path', '/tmp/tmpqprfnza_']
[2025-03-19T17:39:06.585+0000] {standard_task_runner.py:85} INFO - Job 2451: Subtask store_data_hdfs
[2025-03-19T17:39:06.765+0000] {task_command.py:415} INFO - Running <TaskInstance: faud_detection_pipeline.store_data_hdfs scheduled__2023-10-14T08:00:00+00:00 [running]> on host 0009f5fb76aa
[2025-03-19T17:39:07.020+0000] {taskinstance.py:1660} INFO - Exporting env vars: AIRFLOW_CTX_DAG_OWNER='***' AIRFLOW_CTX_DAG_ID='faud_detection_pipeline' AIRFLOW_CTX_TASK_ID='store_data_hdfs' AIRFLOW_CTX_EXECUTION_DATE='2023-10-14T08:00:00+00:00' AIRFLOW_CTX_TRY_NUMBER='1' AIRFLOW_CTX_DAG_RUN_ID='scheduled__2023-10-14T08:00:00+00:00'
[2025-03-19T17:39:07.027+0000] {subprocess.py:63} INFO - Tmp dir root location: /tmp
[2025-03-19T17:39:07.029+0000] {subprocess.py:75} INFO - Running command: ['/bin/bash', '-c', 'docker cp /tmp/transactions.csv namenode:/tmp/transactions.csv && docker cp /tmp/customers.csv namenode:/tmp/customers.csv && docker cp /tmp/external_data.csv namenode:/tmp/external_data.csv && docker exec namenode bash -c "hdfs dfs -mkdir -p /data/transactions && hdfs dfs -mkdir -p /data/customers && hdfs dfs -mkdir -p /data/external_data && hdfs dfs -put -f /tmp/transactions.csv /data/transactions/transactions.csv && hdfs dfs -put -f /tmp/customers.csv /data/customers/customers.csv && hdfs dfs -put -f /tmp/external_data.csv /data/external_data/external_data.csv && rm -rf /tmp/transactions.csv /tmp/customers.csv /tmp/external_data.csv"']
[2025-03-19T17:39:07.054+0000] {subprocess.py:86} INFO - Output:
[2025-03-19T19:10:22.087+0000] {subprocess.py:93} INFO - 2025-03-19 19:10:22,083 INFO sasl.SaslDataTransferClient: SASL encryption trust check: localHostTrusted = false, remoteHostTrusted = false
[2025-03-19T19:10:37.392+0000] {subprocess.py:93} INFO - 2025-03-19 19:10:37,377 INFO sasl.SaslDataTransferClient: SASL encryption trust check: localHostTrusted = false, remoteHostTrusted = false
[2025-03-19T19:10:47.632+0000] {local_task_job_runner.py:294} WARNING - State of this instance has been externally set to up_for_retry. Terminating instance.
[2025-03-19T19:10:47.663+0000] {process_utils.py:131} INFO - Sending 15 to group 36572. PIDs of all processes in the group: [36573, 36572]
[2025-03-19T19:10:47.669+0000] {process_utils.py:86} INFO - Sending the signal 15 to group 36572
[2025-03-19T19:10:47.670+0000] {taskinstance.py:1630} ERROR - Received SIGTERM. Terminating subprocesses.
[2025-03-19T19:10:47.676+0000] {subprocess.py:104} INFO - Sending SIGTERM signal to process group
[2025-03-19T19:10:47.740+0000] {taskinstance.py:1935} ERROR - Task failed with exception
Traceback (most recent call last):
  File "/home/airflow/.local/lib/python3.8/site-packages/airflow/operators/bash.py", line 201, in execute
    result = self.subprocess_hook.run_command(
  File "/home/airflow/.local/lib/python3.8/site-packages/airflow/hooks/subprocess.py", line 91, in run_command
    for raw_line in iter(self.sub_process.stdout.readline, b""):
  File "/home/airflow/.local/lib/python3.8/site-packages/airflow/models/taskinstance.py", line 1632, in signal_handler
    raise AirflowException("Task received SIGTERM signal")
airflow.exceptions.AirflowException: Task received SIGTERM signal
[2025-03-19T19:10:47.790+0000] {taskinstance.py:1398} INFO - Marking task as FAILED. dag_id=faud_detection_pipeline, task_id=store_data_hdfs, execution_date=20231014T080000, start_date=20250319T173906, end_date=20250319T191047
[2025-03-19T19:10:47.866+0000] {standard_task_runner.py:104} ERROR - Failed to execute job 2451 for task store_data_hdfs (Task received SIGTERM signal; 36572)
[2025-03-19T19:10:47.951+0000] {process_utils.py:79} INFO - Process psutil.Process(pid=36573, status='terminated', started='17:39:06') (36573) terminated with exit code None
[2025-03-19T19:10:47.953+0000] {process_utils.py:79} INFO - Process psutil.Process(pid=36572, status='terminated', exitcode=1, started='17:39:05') (36572) terminated with exit code 1
