[2025-03-21T13:33:29.176+0000] {taskinstance.py:1157} INFO - Dependencies all met for dep_context=non-requeueable deps ti=<TaskInstance: test_fraud_detection_pipeline.store_data_hdfs manual__2025-03-21T13:33:25.968865+00:00 [queued]>
[2025-03-21T13:33:29.189+0000] {taskinstance.py:1157} INFO - Dependencies all met for dep_context=requeueable deps ti=<TaskInstance: test_fraud_detection_pipeline.store_data_hdfs manual__2025-03-21T13:33:25.968865+00:00 [queued]>
[2025-03-21T13:33:29.190+0000] {taskinstance.py:1359} INFO - Starting attempt 1 of 4
[2025-03-21T13:33:29.211+0000] {taskinstance.py:1380} INFO - Executing <Task(BashOperator): store_data_hdfs> on 2025-03-21 13:33:25.968865+00:00
[2025-03-21T13:33:29.219+0000] {standard_task_runner.py:57} INFO - Started process 31562 to run task
[2025-03-21T13:33:29.223+0000] {standard_task_runner.py:84} INFO - Running: ['***', 'tasks', 'run', 'test_fraud_detection_pipeline', 'store_data_hdfs', 'manual__2025-03-21T13:33:25.968865+00:00', '--job-id', '3586', '--raw', '--subdir', 'DAGS_FOLDER/dag_2.py', '--cfg-path', '/tmp/tmp_slntyzw']
[2025-03-21T13:33:29.226+0000] {standard_task_runner.py:85} INFO - Job 3586: Subtask store_data_hdfs
[2025-03-21T13:33:29.287+0000] {task_command.py:415} INFO - Running <TaskInstance: test_fraud_detection_pipeline.store_data_hdfs manual__2025-03-21T13:33:25.968865+00:00 [running]> on host 445fc0f18383
[2025-03-21T13:33:29.382+0000] {taskinstance.py:1660} INFO - Exporting env vars: AIRFLOW_CTX_DAG_EMAIL='abelchaguermohamed@gmail.com' AIRFLOW_CTX_DAG_OWNER='***' AIRFLOW_CTX_DAG_ID='test_fraud_detection_pipeline' AIRFLOW_CTX_TASK_ID='store_data_hdfs' AIRFLOW_CTX_EXECUTION_DATE='2025-03-21T13:33:25.968865+00:00' AIRFLOW_CTX_TRY_NUMBER='1' AIRFLOW_CTX_DAG_RUN_ID='manual__2025-03-21T13:33:25.968865+00:00'
[2025-03-21T13:33:29.384+0000] {subprocess.py:63} INFO - Tmp dir root location: /tmp
[2025-03-21T13:33:29.385+0000] {subprocess.py:75} INFO - Running command: ['/bin/bash', '-c', 'docker cp /tmp/transactions.csv namenode:/tmp/transactions.csv && docker cp /tmp/customers.csv namenode:/tmp/customers.csv && docker cp /tmp/external_data.csv namenode:/tmp/external_data.csv && docker exec namenode bash -c "hdfs dfs -mkdir -p /data/transactions && hdfs dfs -mkdir -p /data/customers && hdfs dfs -mkdir -p /data/external_data && hdfs dfs -put -f /tmp/transactions.csv /data/transactions/transactions.csv && hdfs dfs -put -f /tmp/customers.csv /data/customers/customers.csv && hdfs dfs -put -f /tmp/external_data.csv /data/external_data/external_data.csv && rm -rf /tmp/transactions.csv /tmp/customers.csv /tmp/external_data.csv"']
[2025-03-21T13:33:29.399+0000] {subprocess.py:86} INFO - Output:
[2025-03-21T13:33:35.878+0000] {subprocess.py:93} INFO - 2025-03-21 13:33:35,875 INFO sasl.SaslDataTransferClient: SASL encryption trust check: localHostTrusted = false, remoteHostTrusted = false
[2025-03-21T13:33:38.041+0000] {subprocess.py:93} INFO - 2025-03-21 13:33:38,038 INFO sasl.SaslDataTransferClient: SASL encryption trust check: localHostTrusted = false, remoteHostTrusted = false
[2025-03-21T13:33:40.385+0000] {subprocess.py:93} INFO - 2025-03-21 13:33:40,383 INFO sasl.SaslDataTransferClient: SASL encryption trust check: localHostTrusted = false, remoteHostTrusted = false
[2025-03-21T13:33:41.033+0000] {subprocess.py:97} INFO - Command exited with return code 0
[2025-03-21T13:33:41.064+0000] {taskinstance.py:1398} INFO - Marking task as SUCCESS. dag_id=test_fraud_detection_pipeline, task_id=store_data_hdfs, execution_date=20250321T133325, start_date=20250321T133329, end_date=20250321T133341
[2025-03-21T13:33:41.080+0000] {logging_mixin.py:151} WARNING - /home/***/.local/lib/python3.8/site-packages/***/utils/email.py:154 RemovedInAirflow3Warning: Fetching SMTP credentials from configuration variables will be deprecated in a future release. Please set credentials using a connection instead.
[2025-03-21T13:33:41.081+0000] {configuration.py:1063} WARNING - section/key [smtp/smtp_user] not found in config
[2025-03-21T13:33:41.082+0000] {email.py:270} INFO - Email alerting: attempt 1
[2025-03-21T13:33:41.084+0000] {taskinstance.py:1703} ERROR - Error when executing notify_success callback
Traceback (most recent call last):
  File "/home/airflow/.local/lib/python3.8/site-packages/airflow/models/taskinstance.py", line 1700, in _run_finished_callback
    callback(context)
  File "/opt/airflow/dags/dag_2.py", line 29, in notify_success
    send_email(to=email, subject=subject, html_content=html_content)
  File "/home/airflow/.local/lib/python3.8/site-packages/airflow/utils/email.py", line 80, in send_email
    return backend(
  File "/home/airflow/.local/lib/python3.8/site-packages/airflow/utils/email.py", line 154, in send_email_smtp
    send_mime_email(e_from=mail_from, e_to=recipients, mime_msg=msg, conn_id=conn_id, dryrun=dryrun)
  File "/home/airflow/.local/lib/python3.8/site-packages/airflow/utils/email.py", line 272, in send_mime_email
    smtp_conn = _get_smtp_connection(smtp_host, smtp_port, smtp_timeout, smtp_ssl)
  File "/home/airflow/.local/lib/python3.8/site-packages/airflow/utils/email.py", line 317, in _get_smtp_connection
    return smtplib.SMTP(host=host, port=port, timeout=timeout)
  File "/usr/local/lib/python3.8/smtplib.py", line 255, in __init__
    (code, msg) = self.connect(host, port)
  File "/usr/local/lib/python3.8/smtplib.py", line 339, in connect
    self.sock = self._get_socket(host, port, self.timeout)
  File "/usr/local/lib/python3.8/smtplib.py", line 310, in _get_socket
    return socket.create_connection((host, port), timeout,
  File "/usr/local/lib/python3.8/socket.py", line 808, in create_connection
    raise err
  File "/usr/local/lib/python3.8/socket.py", line 796, in create_connection
    sock.connect(sa)
ConnectionRefusedError: [Errno 111] Connection refused
[2025-03-21T13:33:41.138+0000] {local_task_job_runner.py:228} INFO - Task exited with return code 0
[2025-03-21T13:33:41.172+0000] {taskinstance.py:2776} INFO - 1 downstream tasks scheduled from follow-on schedule check
