[2025-03-19T17:12:37.538+0000] {taskinstance.py:1157} INFO - Dependencies all met for dep_context=non-requeueable deps ti=<TaskInstance: faud_detection_pipeline.store_data_hdfs scheduled__2023-10-11T01:00:00+00:00 [queued]>
[2025-03-19T17:12:37.609+0000] {taskinstance.py:1157} INFO - Dependencies all met for dep_context=requeueable deps ti=<TaskInstance: faud_detection_pipeline.store_data_hdfs scheduled__2023-10-11T01:00:00+00:00 [queued]>
[2025-03-19T17:12:37.616+0000] {taskinstance.py:1359} INFO - Starting attempt 2 of 2
[2025-03-19T17:12:37.717+0000] {taskinstance.py:1380} INFO - Executing <Task(BashOperator): store_data_hdfs> on 2023-10-11 01:00:00+00:00
[2025-03-19T17:12:37.738+0000] {standard_task_runner.py:57} INFO - Started process 30747 to run task
[2025-03-19T17:12:37.811+0000] {standard_task_runner.py:84} INFO - Running: ['***', 'tasks', 'run', 'faud_detection_pipeline', 'store_data_hdfs', 'scheduled__2023-10-11T01:00:00+00:00', '--job-id', '2183', '--raw', '--subdir', 'DAGS_FOLDER/dag_1.py', '--cfg-path', '/tmp/tmpwdeovq0k']
[2025-03-19T17:12:37.828+0000] {standard_task_runner.py:85} INFO - Job 2183: Subtask store_data_hdfs
[2025-03-19T17:12:38.171+0000] {task_command.py:415} INFO - Running <TaskInstance: faud_detection_pipeline.store_data_hdfs scheduled__2023-10-11T01:00:00+00:00 [running]> on host 0009f5fb76aa
[2025-03-19T17:12:38.631+0000] {taskinstance.py:1660} INFO - Exporting env vars: AIRFLOW_CTX_DAG_OWNER='***' AIRFLOW_CTX_DAG_ID='faud_detection_pipeline' AIRFLOW_CTX_TASK_ID='store_data_hdfs' AIRFLOW_CTX_EXECUTION_DATE='2023-10-11T01:00:00+00:00' AIRFLOW_CTX_TRY_NUMBER='2' AIRFLOW_CTX_DAG_RUN_ID='scheduled__2023-10-11T01:00:00+00:00'
[2025-03-19T17:12:38.641+0000] {subprocess.py:63} INFO - Tmp dir root location: /tmp
[2025-03-19T17:12:38.656+0000] {subprocess.py:75} INFO - Running command: ['/bin/bash', '-c', 'docker cp /tmp/transactions.csv namenode:/tmp/transactions.csv && docker cp /tmp/customers.csv namenode:/tmp/customers.csv && docker cp /tmp/external_data.csv namenode:/tmp/external_data.csv && docker exec namenode bash -c "hdfs dfs -mkdir -p /data/transactions && hdfs dfs -mkdir -p /data/customers && hdfs dfs -mkdir -p /data/external_data && hdfs dfs -put -f /tmp/transactions.csv /data/transactions/transactions.csv && hdfs dfs -put -f /tmp/customers.csv /data/customers/customers.csv && hdfs dfs -put -f /tmp/external_data.csv /data/external_data/external_data.csv && rm -rf /tmp/transactions.csv /tmp/customers.csv /tmp/external_data.csv"']
[2025-03-19T17:12:38.702+0000] {subprocess.py:86} INFO - Output:
[2025-03-19T17:13:16.033+0000] {subprocess.py:93} INFO - 2025-03-19 17:13:16,015 WARN hdfs.DataStreamer: DataStreamer Exception
[2025-03-19T17:13:16.036+0000] {subprocess.py:93} INFO - java.io.FileNotFoundException: File does not exist: /data/transactions/transactions.csv._COPYING_ (inode 17387) Holder DFSClient_NONMAPREDUCE_-1400684399_1 does not have any open files.
[2025-03-19T17:13:16.037+0000] {subprocess.py:93} INFO - 	at org.apache.hadoop.hdfs.server.namenode.FSNamesystem.checkLease(FSNamesystem.java:2898)
[2025-03-19T17:13:16.038+0000] {subprocess.py:93} INFO - 	at org.apache.hadoop.hdfs.server.namenode.FSDirWriteFileOp.analyzeFileState(FSDirWriteFileOp.java:599)
[2025-03-19T17:13:16.039+0000] {subprocess.py:93} INFO - 	at org.apache.hadoop.hdfs.server.namenode.FSDirWriteFileOp.validateAddBlock(FSDirWriteFileOp.java:171)
[2025-03-19T17:13:16.040+0000] {subprocess.py:93} INFO - 	at org.apache.hadoop.hdfs.server.namenode.FSNamesystem.getAdditionalBlock(FSNamesystem.java:2777)
[2025-03-19T17:13:16.041+0000] {subprocess.py:93} INFO - 	at org.apache.hadoop.hdfs.server.namenode.NameNodeRpcServer.addBlock(NameNodeRpcServer.java:892)
[2025-03-19T17:13:16.042+0000] {subprocess.py:93} INFO - 	at org.apache.hadoop.hdfs.protocolPB.ClientNamenodeProtocolServerSideTranslatorPB.addBlock(ClientNamenodeProtocolServerSideTranslatorPB.java:574)
[2025-03-19T17:13:16.042+0000] {subprocess.py:93} INFO - 	at org.apache.hadoop.hdfs.protocol.proto.ClientNamenodeProtocolProtos$ClientNamenodeProtocol$2.callBlockingMethod(ClientNamenodeProtocolProtos.java)
[2025-03-19T17:13:16.043+0000] {subprocess.py:93} INFO - 	at org.apache.hadoop.ipc.ProtobufRpcEngine$Server$ProtoBufRpcInvoker.call(ProtobufRpcEngine.java:528)
[2025-03-19T17:13:16.045+0000] {subprocess.py:93} INFO - 	at org.apache.hadoop.ipc.RPC$Server.call(RPC.java:1070)
[2025-03-19T17:13:16.046+0000] {subprocess.py:93} INFO - 	at org.apache.hadoop.ipc.Server$RpcCall.run(Server.java:999)
[2025-03-19T17:13:16.047+0000] {subprocess.py:93} INFO - 	at org.apache.hadoop.ipc.Server$RpcCall.run(Server.java:927)
[2025-03-19T17:13:16.048+0000] {subprocess.py:93} INFO - 	at java.security.AccessController.doPrivileged(Native Method)
[2025-03-19T17:13:16.048+0000] {subprocess.py:93} INFO - 	at javax.security.auth.Subject.doAs(Subject.java:422)
[2025-03-19T17:13:16.050+0000] {subprocess.py:93} INFO - 	at org.apache.hadoop.security.UserGroupInformation.doAs(UserGroupInformation.java:1730)
[2025-03-19T17:13:16.053+0000] {subprocess.py:93} INFO - 	at org.apache.hadoop.ipc.Server$Handler.run(Server.java:2915)
[2025-03-19T17:13:16.055+0000] {subprocess.py:93} INFO - 
[2025-03-19T17:13:16.056+0000] {subprocess.py:93} INFO - 	at sun.reflect.NativeConstructorAccessorImpl.newInstance0(Native Method)
[2025-03-19T17:13:16.059+0000] {subprocess.py:93} INFO - 	at sun.reflect.NativeConstructorAccessorImpl.newInstance(NativeConstructorAccessorImpl.java:62)
[2025-03-19T17:13:16.060+0000] {subprocess.py:93} INFO - 	at sun.reflect.DelegatingConstructorAccessorImpl.newInstance(DelegatingConstructorAccessorImpl.java:45)
[2025-03-19T17:13:16.061+0000] {subprocess.py:93} INFO - 	at java.lang.reflect.Constructor.newInstance(Constructor.java:423)
[2025-03-19T17:13:16.062+0000] {subprocess.py:93} INFO - 	at org.apache.hadoop.ipc.RemoteException.instantiateException(RemoteException.java:121)
[2025-03-19T17:13:16.063+0000] {subprocess.py:93} INFO - 	at org.apache.hadoop.ipc.RemoteException.unwrapRemoteException(RemoteException.java:88)
[2025-03-19T17:13:16.064+0000] {subprocess.py:93} INFO - 	at org.apache.hadoop.hdfs.DFSOutputStream.addBlock(DFSOutputStream.java:1084)
[2025-03-19T17:13:16.066+0000] {subprocess.py:93} INFO - 	at org.apache.hadoop.hdfs.DataStreamer.locateFollowingBlock(DataStreamer.java:1866)
[2025-03-19T17:13:16.067+0000] {subprocess.py:93} INFO - 	at org.apache.hadoop.hdfs.DataStreamer.nextBlockOutputStream(DataStreamer.java:1668)
[2025-03-19T17:13:16.068+0000] {subprocess.py:93} INFO - 	at org.apache.hadoop.hdfs.DataStreamer.run(DataStreamer.java:716)
[2025-03-19T17:13:16.069+0000] {subprocess.py:93} INFO - Caused by: org.apache.hadoop.ipc.RemoteException(java.io.FileNotFoundException): File does not exist: /data/transactions/transactions.csv._COPYING_ (inode 17387) Holder DFSClient_NONMAPREDUCE_-1400684399_1 does not have any open files.
[2025-03-19T17:13:16.069+0000] {subprocess.py:93} INFO - 	at org.apache.hadoop.hdfs.server.namenode.FSNamesystem.checkLease(FSNamesystem.java:2898)
[2025-03-19T17:13:16.070+0000] {subprocess.py:93} INFO - 	at org.apache.hadoop.hdfs.server.namenode.FSDirWriteFileOp.analyzeFileState(FSDirWriteFileOp.java:599)
[2025-03-19T17:13:16.071+0000] {subprocess.py:93} INFO - 	at org.apache.hadoop.hdfs.server.namenode.FSDirWriteFileOp.validateAddBlock(FSDirWriteFileOp.java:171)
[2025-03-19T17:13:16.071+0000] {subprocess.py:93} INFO - 	at org.apache.hadoop.hdfs.server.namenode.FSNamesystem.getAdditionalBlock(FSNamesystem.java:2777)
[2025-03-19T17:13:16.072+0000] {subprocess.py:93} INFO - 	at org.apache.hadoop.hdfs.server.namenode.NameNodeRpcServer.addBlock(NameNodeRpcServer.java:892)
[2025-03-19T17:13:16.072+0000] {subprocess.py:93} INFO - 	at org.apache.hadoop.hdfs.protocolPB.ClientNamenodeProtocolServerSideTranslatorPB.addBlock(ClientNamenodeProtocolServerSideTranslatorPB.java:574)
[2025-03-19T17:13:16.073+0000] {subprocess.py:93} INFO - 	at org.apache.hadoop.hdfs.protocol.proto.ClientNamenodeProtocolProtos$ClientNamenodeProtocol$2.callBlockingMethod(ClientNamenodeProtocolProtos.java)
[2025-03-19T17:13:16.075+0000] {subprocess.py:93} INFO - 	at org.apache.hadoop.ipc.ProtobufRpcEngine$Server$ProtoBufRpcInvoker.call(ProtobufRpcEngine.java:528)
[2025-03-19T17:13:16.077+0000] {subprocess.py:93} INFO - 	at org.apache.hadoop.ipc.RPC$Server.call(RPC.java:1070)
[2025-03-19T17:13:16.078+0000] {subprocess.py:93} INFO - 	at org.apache.hadoop.ipc.Server$RpcCall.run(Server.java:999)
[2025-03-19T17:13:16.079+0000] {subprocess.py:93} INFO - 	at org.apache.hadoop.ipc.Server$RpcCall.run(Server.java:927)
[2025-03-19T17:13:16.080+0000] {subprocess.py:93} INFO - 	at java.security.AccessController.doPrivileged(Native Method)
[2025-03-19T17:13:16.080+0000] {subprocess.py:93} INFO - 	at javax.security.auth.Subject.doAs(Subject.java:422)
[2025-03-19T17:13:16.081+0000] {subprocess.py:93} INFO - 	at org.apache.hadoop.security.UserGroupInformation.doAs(UserGroupInformation.java:1730)
[2025-03-19T17:13:16.082+0000] {subprocess.py:93} INFO - 	at org.apache.hadoop.ipc.Server$Handler.run(Server.java:2915)
[2025-03-19T17:13:16.083+0000] {subprocess.py:93} INFO - 
[2025-03-19T17:13:16.084+0000] {subprocess.py:93} INFO - 	at org.apache.hadoop.ipc.Client.getRpcResponse(Client.java:1545)
[2025-03-19T17:13:16.084+0000] {subprocess.py:93} INFO - 	at org.apache.hadoop.ipc.Client.call(Client.java:1491)
[2025-03-19T17:13:16.085+0000] {subprocess.py:93} INFO - 	at org.apache.hadoop.ipc.Client.call(Client.java:1388)
[2025-03-19T17:13:16.086+0000] {subprocess.py:93} INFO - 	at org.apache.hadoop.ipc.ProtobufRpcEngine$Invoker.invoke(ProtobufRpcEngine.java:233)
[2025-03-19T17:13:16.086+0000] {subprocess.py:93} INFO - 	at org.apache.hadoop.ipc.ProtobufRpcEngine$Invoker.invoke(ProtobufRpcEngine.java:118)
[2025-03-19T17:13:16.087+0000] {subprocess.py:93} INFO - 	at com.sun.proxy.$Proxy9.addBlock(Unknown Source)
[2025-03-19T17:13:16.088+0000] {subprocess.py:93} INFO - 	at org.apache.hadoop.hdfs.protocolPB.ClientNamenodeProtocolTranslatorPB.addBlock(ClientNamenodeProtocolTranslatorPB.java:517)
[2025-03-19T17:13:16.089+0000] {subprocess.py:93} INFO - 	at sun.reflect.NativeMethodAccessorImpl.invoke0(Native Method)
[2025-03-19T17:13:16.090+0000] {subprocess.py:93} INFO - 	at sun.reflect.NativeMethodAccessorImpl.invoke(NativeMethodAccessorImpl.java:62)
[2025-03-19T17:13:16.091+0000] {subprocess.py:93} INFO - 	at sun.reflect.DelegatingMethodAccessorImpl.invoke(DelegatingMethodAccessorImpl.java:43)
[2025-03-19T17:13:16.092+0000] {subprocess.py:93} INFO - 	at java.lang.reflect.Method.invoke(Method.java:498)
[2025-03-19T17:13:16.097+0000] {subprocess.py:93} INFO - 	at org.apache.hadoop.io.retry.RetryInvocationHandler.invokeMethod(RetryInvocationHandler.java:422)
[2025-03-19T17:13:16.099+0000] {subprocess.py:93} INFO - 	at org.apache.hadoop.io.retry.RetryInvocationHandler$Call.invokeMethod(RetryInvocationHandler.java:165)
[2025-03-19T17:13:16.101+0000] {subprocess.py:93} INFO - 	at org.apache.hadoop.io.retry.RetryInvocationHandler$Call.invoke(RetryInvocationHandler.java:157)
[2025-03-19T17:13:16.101+0000] {subprocess.py:93} INFO - 	at org.apache.hadoop.io.retry.RetryInvocationHandler$Call.invokeOnce(RetryInvocationHandler.java:95)
[2025-03-19T17:13:16.102+0000] {subprocess.py:93} INFO - 	at org.apache.hadoop.io.retry.RetryInvocationHandler.invoke(RetryInvocationHandler.java:359)
[2025-03-19T17:13:16.103+0000] {subprocess.py:93} INFO - 	at com.sun.proxy.$Proxy10.addBlock(Unknown Source)
[2025-03-19T17:13:16.104+0000] {subprocess.py:93} INFO - 	at org.apache.hadoop.hdfs.DFSOutputStream.addBlock(DFSOutputStream.java:1081)
[2025-03-19T17:13:16.106+0000] {subprocess.py:93} INFO - 	... 3 more
[2025-03-19T17:13:16.107+0000] {subprocess.py:93} INFO - put: File does not exist: /data/transactions/transactions.csv._COPYING_ (inode 17387) Holder DFSClient_NONMAPREDUCE_-1400684399_1 does not have any open files.
[2025-03-19T17:13:16.562+0000] {subprocess.py:97} INFO - Command exited with return code 1
[2025-03-19T17:13:16.586+0000] {taskinstance.py:1935} ERROR - Task failed with exception
Traceback (most recent call last):
  File "/home/airflow/.local/lib/python3.8/site-packages/airflow/operators/bash.py", line 210, in execute
    raise AirflowException(
airflow.exceptions.AirflowException: Bash command failed. The command returned a non-zero exit code 1.
[2025-03-19T17:13:16.597+0000] {taskinstance.py:1398} INFO - Marking task as FAILED. dag_id=faud_detection_pipeline, task_id=store_data_hdfs, execution_date=20231011T010000, start_date=20250319T171237, end_date=20250319T171316
[2025-03-19T17:13:16.908+0000] {standard_task_runner.py:104} ERROR - Failed to execute job 2183 for task store_data_hdfs (Bash command failed. The command returned a non-zero exit code 1.; 30747)
[2025-03-19T17:13:16.953+0000] {local_task_job_runner.py:228} INFO - Task exited with return code 1
[2025-03-19T17:13:17.008+0000] {taskinstance.py:2776} INFO - 0 downstream tasks scheduled from follow-on schedule check
