[2025-03-19T21:09:58.998+0000] {taskinstance.py:1157} INFO - Dependencies all met for dep_context=non-requeueable deps ti=<TaskInstance: faud_detection_pipeline.store_data_hdfs scheduled__2023-10-21T06:00:00+00:00 [queued]>
[2025-03-19T21:09:59.086+0000] {taskinstance.py:1157} INFO - Dependencies all met for dep_context=requeueable deps ti=<TaskInstance: faud_detection_pipeline.store_data_hdfs scheduled__2023-10-21T06:00:00+00:00 [queued]>
[2025-03-19T21:09:59.090+0000] {taskinstance.py:1359} INFO - Starting attempt 1 of 1
[2025-03-19T21:09:59.201+0000] {taskinstance.py:1380} INFO - Executing <Task(BashOperator): store_data_hdfs> on 2023-10-21 06:00:00+00:00
[2025-03-19T21:09:59.212+0000] {standard_task_runner.py:57} INFO - Started process 2804 to run task
[2025-03-19T21:09:59.229+0000] {standard_task_runner.py:84} INFO - Running: ['***', 'tasks', 'run', 'faud_detection_pipeline', 'store_data_hdfs', 'scheduled__2023-10-21T06:00:00+00:00', '--job-id', '3057', '--raw', '--subdir', 'DAGS_FOLDER/dag_1.py', '--cfg-path', '/tmp/tmpz_nm5o15']
[2025-03-19T21:09:59.344+0000] {standard_task_runner.py:85} INFO - Job 3057: Subtask store_data_hdfs
[2025-03-19T21:09:59.886+0000] {task_command.py:415} INFO - Running <TaskInstance: faud_detection_pipeline.store_data_hdfs scheduled__2023-10-21T06:00:00+00:00 [running]> on host 445fc0f18383
[2025-03-19T21:10:00.626+0000] {taskinstance.py:1660} INFO - Exporting env vars: AIRFLOW_CTX_DAG_OWNER='***' AIRFLOW_CTX_DAG_ID='faud_detection_pipeline' AIRFLOW_CTX_TASK_ID='store_data_hdfs' AIRFLOW_CTX_EXECUTION_DATE='2023-10-21T06:00:00+00:00' AIRFLOW_CTX_TRY_NUMBER='1' AIRFLOW_CTX_DAG_RUN_ID='scheduled__2023-10-21T06:00:00+00:00'
[2025-03-19T21:10:00.638+0000] {subprocess.py:63} INFO - Tmp dir root location: /tmp
[2025-03-19T21:10:00.648+0000] {subprocess.py:75} INFO - Running command: ['/bin/bash', '-c', 'docker cp /tmp/transactions.csv namenode:/tmp/transactions.csv && docker cp /tmp/customers.csv namenode:/tmp/customers.csv && docker cp /tmp/external_data.csv namenode:/tmp/external_data.csv && docker exec namenode bash -c "hdfs dfs -mkdir -p /data/transactions && hdfs dfs -mkdir -p /data/customers && hdfs dfs -mkdir -p /data/external_data && hdfs dfs -put -f /tmp/transactions.csv /data/transactions/transactions.csv && hdfs dfs -put -f /tmp/customers.csv /data/customers/customers.csv && hdfs dfs -put -f /tmp/external_data.csv /data/external_data/external_data.csv && rm -rf /tmp/transactions.csv /tmp/customers.csv /tmp/external_data.csv"']
[2025-03-19T21:10:00.731+0000] {subprocess.py:86} INFO - Output:
[2025-03-19T21:11:13.493+0000] {subprocess.py:93} INFO - 2025-03-19 21:11:13,391 WARN hdfs.DataStreamer: DataStreamer Exception
[2025-03-19T21:11:13.495+0000] {subprocess.py:93} INFO - java.io.FileNotFoundException: File does not exist: /data/transactions/transactions.csv._COPYING_ (inode 17974) Holder DFSClient_NONMAPREDUCE_-1503519187_1 does not have any open files.
[2025-03-19T21:11:13.512+0000] {subprocess.py:93} INFO - 	at org.apache.hadoop.hdfs.server.namenode.FSNamesystem.checkLease(FSNamesystem.java:2898)
[2025-03-19T21:11:13.528+0000] {subprocess.py:93} INFO - 	at org.apache.hadoop.hdfs.server.namenode.FSDirWriteFileOp.analyzeFileState(FSDirWriteFileOp.java:599)
[2025-03-19T21:11:13.552+0000] {subprocess.py:93} INFO - 	at org.apache.hadoop.hdfs.server.namenode.FSDirWriteFileOp.validateAddBlock(FSDirWriteFileOp.java:171)
[2025-03-19T21:11:13.598+0000] {subprocess.py:93} INFO - 	at org.apache.hadoop.hdfs.server.namenode.FSNamesystem.getAdditionalBlock(FSNamesystem.java:2777)
[2025-03-19T21:11:13.611+0000] {subprocess.py:93} INFO - 	at org.apache.hadoop.hdfs.server.namenode.NameNodeRpcServer.addBlock(NameNodeRpcServer.java:892)
[2025-03-19T21:11:13.622+0000] {subprocess.py:93} INFO - 	at org.apache.hadoop.hdfs.protocolPB.ClientNamenodeProtocolServerSideTranslatorPB.addBlock(ClientNamenodeProtocolServerSideTranslatorPB.java:574)
[2025-03-19T21:11:13.623+0000] {subprocess.py:93} INFO - 	at org.apache.hadoop.hdfs.protocol.proto.ClientNamenodeProtocolProtos$ClientNamenodeProtocol$2.callBlockingMethod(ClientNamenodeProtocolProtos.java)
[2025-03-19T21:11:13.624+0000] {subprocess.py:93} INFO - 	at org.apache.hadoop.ipc.ProtobufRpcEngine$Server$ProtoBufRpcInvoker.call(ProtobufRpcEngine.java:528)
[2025-03-19T21:11:13.625+0000] {subprocess.py:93} INFO - 	at org.apache.hadoop.ipc.RPC$Server.call(RPC.java:1070)
[2025-03-19T21:11:13.651+0000] {subprocess.py:93} INFO - 	at org.apache.hadoop.ipc.Server$RpcCall.run(Server.java:999)
[2025-03-19T21:11:13.659+0000] {subprocess.py:93} INFO - 	at org.apache.hadoop.ipc.Server$RpcCall.run(Server.java:927)
[2025-03-19T21:11:13.661+0000] {subprocess.py:93} INFO - 	at java.security.AccessController.doPrivileged(Native Method)
[2025-03-19T21:11:13.671+0000] {subprocess.py:93} INFO - 	at javax.security.auth.Subject.doAs(Subject.java:422)
[2025-03-19T21:11:13.677+0000] {subprocess.py:93} INFO - 	at org.apache.hadoop.security.UserGroupInformation.doAs(UserGroupInformation.java:1730)
[2025-03-19T21:11:13.687+0000] {subprocess.py:93} INFO - 	at org.apache.hadoop.ipc.Server$Handler.run(Server.java:2915)
[2025-03-19T21:11:13.706+0000] {subprocess.py:93} INFO - 
[2025-03-19T21:11:13.720+0000] {subprocess.py:93} INFO - 	at sun.reflect.NativeConstructorAccessorImpl.newInstance0(Native Method)
[2025-03-19T21:11:13.737+0000] {subprocess.py:93} INFO - 	at sun.reflect.NativeConstructorAccessorImpl.newInstance(NativeConstructorAccessorImpl.java:62)
[2025-03-19T21:11:13.753+0000] {subprocess.py:93} INFO - 	at sun.reflect.DelegatingConstructorAccessorImpl.newInstance(DelegatingConstructorAccessorImpl.java:45)
[2025-03-19T21:11:13.769+0000] {subprocess.py:93} INFO - 	at java.lang.reflect.Constructor.newInstance(Constructor.java:423)
[2025-03-19T21:11:13.786+0000] {subprocess.py:93} INFO - 	at org.apache.hadoop.ipc.RemoteException.instantiateException(RemoteException.java:121)
[2025-03-19T21:11:13.802+0000] {subprocess.py:93} INFO - 	at org.apache.hadoop.ipc.RemoteException.unwrapRemoteException(RemoteException.java:88)
[2025-03-19T21:11:13.817+0000] {subprocess.py:93} INFO - 	at org.apache.hadoop.hdfs.DFSOutputStream.addBlock(DFSOutputStream.java:1084)
[2025-03-19T21:11:13.838+0000] {subprocess.py:93} INFO - 	at org.apache.hadoop.hdfs.DataStreamer.locateFollowingBlock(DataStreamer.java:1866)
[2025-03-19T21:11:13.850+0000] {subprocess.py:93} INFO - 	at org.apache.hadoop.hdfs.DataStreamer.nextBlockOutputStream(DataStreamer.java:1668)
[2025-03-19T21:11:13.852+0000] {subprocess.py:93} INFO - 	at org.apache.hadoop.hdfs.DataStreamer.run(DataStreamer.java:716)
[2025-03-19T21:11:13.853+0000] {subprocess.py:93} INFO - Caused by: org.apache.hadoop.ipc.RemoteException(java.io.FileNotFoundException): File does not exist: /data/transactions/transactions.csv._COPYING_ (inode 17974) Holder DFSClient_NONMAPREDUCE_-1503519187_1 does not have any open files.
[2025-03-19T21:11:13.854+0000] {subprocess.py:93} INFO - 	at org.apache.hadoop.hdfs.server.namenode.FSNamesystem.checkLease(FSNamesystem.java:2898)
[2025-03-19T21:11:13.866+0000] {subprocess.py:93} INFO - 	at org.apache.hadoop.hdfs.server.namenode.FSDirWriteFileOp.analyzeFileState(FSDirWriteFileOp.java:599)
[2025-03-19T21:11:13.867+0000] {subprocess.py:93} INFO - 	at org.apache.hadoop.hdfs.server.namenode.FSDirWriteFileOp.validateAddBlock(FSDirWriteFileOp.java:171)
[2025-03-19T21:11:13.868+0000] {subprocess.py:93} INFO - 	at org.apache.hadoop.hdfs.server.namenode.FSNamesystem.getAdditionalBlock(FSNamesystem.java:2777)
[2025-03-19T21:11:13.868+0000] {subprocess.py:93} INFO - 	at org.apache.hadoop.hdfs.server.namenode.NameNodeRpcServer.addBlock(NameNodeRpcServer.java:892)
[2025-03-19T21:11:13.869+0000] {subprocess.py:93} INFO - 	at org.apache.hadoop.hdfs.protocolPB.ClientNamenodeProtocolServerSideTranslatorPB.addBlock(ClientNamenodeProtocolServerSideTranslatorPB.java:574)
[2025-03-19T21:11:13.870+0000] {subprocess.py:93} INFO - 	at org.apache.hadoop.hdfs.protocol.proto.ClientNamenodeProtocolProtos$ClientNamenodeProtocol$2.callBlockingMethod(ClientNamenodeProtocolProtos.java)
[2025-03-19T21:11:13.870+0000] {subprocess.py:93} INFO - 	at org.apache.hadoop.ipc.ProtobufRpcEngine$Server$ProtoBufRpcInvoker.call(ProtobufRpcEngine.java:528)
[2025-03-19T21:11:13.883+0000] {subprocess.py:93} INFO - 	at org.apache.hadoop.ipc.RPC$Server.call(RPC.java:1070)
[2025-03-19T21:11:13.884+0000] {subprocess.py:93} INFO - 	at org.apache.hadoop.ipc.Server$RpcCall.run(Server.java:999)
[2025-03-19T21:11:13.885+0000] {subprocess.py:93} INFO - 	at org.apache.hadoop.ipc.Server$RpcCall.run(Server.java:927)
[2025-03-19T21:11:13.885+0000] {subprocess.py:93} INFO - 	at java.security.AccessController.doPrivileged(Native Method)
[2025-03-19T21:11:13.886+0000] {subprocess.py:93} INFO - 	at javax.security.auth.Subject.doAs(Subject.java:422)
[2025-03-19T21:11:13.886+0000] {subprocess.py:93} INFO - 	at org.apache.hadoop.security.UserGroupInformation.doAs(UserGroupInformation.java:1730)
[2025-03-19T21:11:13.887+0000] {subprocess.py:93} INFO - 	at org.apache.hadoop.ipc.Server$Handler.run(Server.java:2915)
[2025-03-19T21:11:13.899+0000] {subprocess.py:93} INFO - 
[2025-03-19T21:11:13.900+0000] {subprocess.py:93} INFO - 	at org.apache.hadoop.ipc.Client.getRpcResponse(Client.java:1545)
[2025-03-19T21:11:13.902+0000] {subprocess.py:93} INFO - 	at org.apache.hadoop.ipc.Client.call(Client.java:1491)
[2025-03-19T21:11:13.903+0000] {subprocess.py:93} INFO - 	at org.apache.hadoop.ipc.Client.call(Client.java:1388)
[2025-03-19T21:11:13.904+0000] {subprocess.py:93} INFO - 	at org.apache.hadoop.ipc.ProtobufRpcEngine$Invoker.invoke(ProtobufRpcEngine.java:233)
[2025-03-19T21:11:13.904+0000] {subprocess.py:93} INFO - 	at org.apache.hadoop.ipc.ProtobufRpcEngine$Invoker.invoke(ProtobufRpcEngine.java:118)
[2025-03-19T21:11:13.905+0000] {subprocess.py:93} INFO - 	at com.sun.proxy.$Proxy9.addBlock(Unknown Source)
[2025-03-19T21:11:13.907+0000] {subprocess.py:93} INFO - 	at org.apache.hadoop.hdfs.protocolPB.ClientNamenodeProtocolTranslatorPB.addBlock(ClientNamenodeProtocolTranslatorPB.java:517)
[2025-03-19T21:11:13.919+0000] {subprocess.py:93} INFO - 	at sun.reflect.NativeMethodAccessorImpl.invoke0(Native Method)
[2025-03-19T21:11:13.920+0000] {subprocess.py:93} INFO - 	at sun.reflect.NativeMethodAccessorImpl.invoke(NativeMethodAccessorImpl.java:62)
[2025-03-19T21:11:13.921+0000] {subprocess.py:93} INFO - 	at sun.reflect.DelegatingMethodAccessorImpl.invoke(DelegatingMethodAccessorImpl.java:43)
[2025-03-19T21:11:13.922+0000] {subprocess.py:93} INFO - 	at java.lang.reflect.Method.invoke(Method.java:498)
[2025-03-19T21:11:13.923+0000] {subprocess.py:93} INFO - 	at org.apache.hadoop.io.retry.RetryInvocationHandler.invokeMethod(RetryInvocationHandler.java:422)
[2025-03-19T21:11:13.936+0000] {subprocess.py:93} INFO - 	at org.apache.hadoop.io.retry.RetryInvocationHandler$Call.invokeMethod(RetryInvocationHandler.java:165)
[2025-03-19T21:11:13.937+0000] {subprocess.py:93} INFO - 	at org.apache.hadoop.io.retry.RetryInvocationHandler$Call.invoke(RetryInvocationHandler.java:157)
[2025-03-19T21:11:13.937+0000] {subprocess.py:93} INFO - 	at org.apache.hadoop.io.retry.RetryInvocationHandler$Call.invokeOnce(RetryInvocationHandler.java:95)
[2025-03-19T21:11:13.938+0000] {subprocess.py:93} INFO - 	at org.apache.hadoop.io.retry.RetryInvocationHandler.invoke(RetryInvocationHandler.java:359)
[2025-03-19T21:11:13.938+0000] {subprocess.py:93} INFO - 	at com.sun.proxy.$Proxy10.addBlock(Unknown Source)
[2025-03-19T21:11:13.939+0000] {subprocess.py:93} INFO - 	at org.apache.hadoop.hdfs.DFSOutputStream.addBlock(DFSOutputStream.java:1081)
[2025-03-19T21:11:13.940+0000] {subprocess.py:93} INFO - 	... 3 more
[2025-03-19T21:11:13.952+0000] {subprocess.py:93} INFO - put: File does not exist: /data/transactions/transactions.csv._COPYING_ (inode 17974) Holder DFSClient_NONMAPREDUCE_-1503519187_1 does not have any open files.
[2025-03-19T21:11:15.139+0000] {subprocess.py:97} INFO - Command exited with return code 1
[2025-03-19T21:11:15.182+0000] {taskinstance.py:1935} ERROR - Task failed with exception
Traceback (most recent call last):
  File "/home/airflow/.local/lib/python3.8/site-packages/airflow/operators/bash.py", line 210, in execute
    raise AirflowException(
airflow.exceptions.AirflowException: Bash command failed. The command returned a non-zero exit code 1.
[2025-03-19T21:11:15.214+0000] {taskinstance.py:1398} INFO - Marking task as FAILED. dag_id=faud_detection_pipeline, task_id=store_data_hdfs, execution_date=20231021T060000, start_date=20250319T210958, end_date=20250319T211115
[2025-03-19T21:11:15.521+0000] {standard_task_runner.py:104} ERROR - Failed to execute job 3057 for task store_data_hdfs (Bash command failed. The command returned a non-zero exit code 1.; 2804)
[2025-03-19T21:11:15.591+0000] {local_task_job_runner.py:228} INFO - Task exited with return code 1
[2025-03-19T21:11:15.790+0000] {taskinstance.py:2776} INFO - 0 downstream tasks scheduled from follow-on schedule check
