[2025-03-19T16:18:45.566+0000] {taskinstance.py:1157} INFO - Dependencies all met for dep_context=non-requeueable deps ti=<TaskInstance: faud_detection_pipeline.fetch_data scheduled__2023-10-06T09:00:00+00:00 [queued]>
[2025-03-19T16:18:45.583+0000] {taskinstance.py:1157} INFO - Dependencies all met for dep_context=requeueable deps ti=<TaskInstance: faud_detection_pipeline.fetch_data scheduled__2023-10-06T09:00:00+00:00 [queued]>
[2025-03-19T16:18:45.585+0000] {taskinstance.py:1359} INFO - Starting attempt 2 of 2
[2025-03-19T16:18:45.610+0000] {taskinstance.py:1380} INFO - Executing <Task(PythonOperator): fetch_data> on 2023-10-06 09:00:00+00:00
[2025-03-19T16:18:45.621+0000] {standard_task_runner.py:57} INFO - Started process 19794 to run task
[2025-03-19T16:18:45.628+0000] {standard_task_runner.py:84} INFO - Running: ['***', 'tasks', 'run', 'faud_detection_pipeline', 'fetch_data', 'scheduled__2023-10-06T09:00:00+00:00', '--job-id', '1678', '--raw', '--subdir', 'DAGS_FOLDER/dag_1.py', '--cfg-path', '/tmp/tmpuato4er6']
[2025-03-19T16:18:45.632+0000] {standard_task_runner.py:85} INFO - Job 1678: Subtask fetch_data
[2025-03-19T16:18:45.719+0000] {task_command.py:415} INFO - Running <TaskInstance: faud_detection_pipeline.fetch_data scheduled__2023-10-06T09:00:00+00:00 [running]> on host 0009f5fb76aa
[2025-03-19T16:18:45.882+0000] {taskinstance.py:1660} INFO - Exporting env vars: AIRFLOW_CTX_DAG_OWNER='***' AIRFLOW_CTX_DAG_ID='faud_detection_pipeline' AIRFLOW_CTX_TASK_ID='fetch_data' AIRFLOW_CTX_EXECUTION_DATE='2023-10-06T09:00:00+00:00' AIRFLOW_CTX_TRY_NUMBER='2' AIRFLOW_CTX_DAG_RUN_ID='scheduled__2023-10-06T09:00:00+00:00'
[2025-03-19T16:18:45.987+0000] {taskinstance.py:1935} ERROR - Task failed with exception
Traceback (most recent call last):
  File "/home/airflow/.local/lib/python3.8/site-packages/airflow/operators/python.py", line 192, in execute
    return_value = self.execute_callable()
  File "/home/airflow/.local/lib/python3.8/site-packages/airflow/operators/python.py", line 209, in execute_callable
    return self.python_callable(*self.op_args, **self.op_kwargs)
  File "/opt/airflow/dags/dag_1.py", line 49, in fetch_data
    write_to_csv(external_data, "/tmp/external_data.csv", fieldnames=external_data[0].keys() if external_data else [])
KeyError: 0
[2025-03-19T16:18:46.002+0000] {taskinstance.py:1398} INFO - Marking task as FAILED. dag_id=faud_detection_pipeline, task_id=fetch_data, execution_date=20231006T090000, start_date=20250319T161845, end_date=20250319T161846
[2025-03-19T16:18:46.022+0000] {standard_task_runner.py:104} ERROR - Failed to execute job 1678 for task fetch_data (0; 19794)
[2025-03-19T16:18:46.048+0000] {local_task_job_runner.py:228} INFO - Task exited with return code 1
[2025-03-19T16:18:46.084+0000] {taskinstance.py:2776} INFO - 0 downstream tasks scheduled from follow-on schedule check
