[2025-03-19T12:05:45.199+0000] {taskinstance.py:1157} INFO - Dependencies all met for dep_context=non-requeueable deps ti=<TaskInstance: fraud_detection_pipeline.run_fraud_detection scheduled__2023-10-07T22:00:00+00:00 [queued]>
[2025-03-19T12:05:45.210+0000] {taskinstance.py:1157} INFO - Dependencies all met for dep_context=requeueable deps ti=<TaskInstance: fraud_detection_pipeline.run_fraud_detection scheduled__2023-10-07T22:00:00+00:00 [queued]>
[2025-03-19T12:05:45.211+0000] {taskinstance.py:1359} INFO - Starting attempt 1 of 2
[2025-03-19T12:05:45.229+0000] {taskinstance.py:1380} INFO - Executing <Task(PythonOperator): run_fraud_detection> on 2023-10-07 22:00:00+00:00
[2025-03-19T12:05:45.236+0000] {standard_task_runner.py:57} INFO - Started process 3754 to run task
[2025-03-19T12:05:45.240+0000] {standard_task_runner.py:84} INFO - Running: ['***', 'tasks', 'run', 'fraud_detection_pipeline', 'run_fraud_detection', 'scheduled__2023-10-07T22:00:00+00:00', '--job-id', '496', '--raw', '--subdir', 'DAGS_FOLDER/dag_1.py', '--cfg-path', '/tmp/tmp_per4rpm']
[2025-03-19T12:05:45.243+0000] {standard_task_runner.py:85} INFO - Job 496: Subtask run_fraud_detection
[2025-03-19T12:05:45.306+0000] {task_command.py:415} INFO - Running <TaskInstance: fraud_detection_pipeline.run_fraud_detection scheduled__2023-10-07T22:00:00+00:00 [running]> on host 0009f5fb76aa
[2025-03-19T12:05:45.448+0000] {taskinstance.py:1660} INFO - Exporting env vars: AIRFLOW_CTX_DAG_OWNER='***' AIRFLOW_CTX_DAG_ID='fraud_detection_pipeline' AIRFLOW_CTX_TASK_ID='run_fraud_detection' AIRFLOW_CTX_EXECUTION_DATE='2023-10-07T22:00:00+00:00' AIRFLOW_CTX_TRY_NUMBER='1' AIRFLOW_CTX_DAG_RUN_ID='scheduled__2023-10-07T22:00:00+00:00'
[2025-03-19T12:05:45.463+0000] {taskinstance.py:1935} ERROR - Task failed with exception
Traceback (most recent call last):
  File "/home/airflow/.local/lib/python3.8/site-packages/airflow/operators/python.py", line 192, in execute
    return_value = self.execute_callable()
  File "/home/airflow/.local/lib/python3.8/site-packages/airflow/operators/python.py", line 209, in execute_callable
    return self.python_callable(*self.op_args, **self.op_kwargs)
  File "/opt/airflow/dags/dag_1.py", line 89, in run_fraud_detection
    subprocess.run(["hive", "-e", query])
  File "/usr/local/lib/python3.8/subprocess.py", line 493, in run
    with Popen(*popenargs, **kwargs) as process:
  File "/usr/local/lib/python3.8/subprocess.py", line 858, in __init__
    self._execute_child(args, executable, preexec_fn, close_fds,
  File "/usr/local/lib/python3.8/subprocess.py", line 1720, in _execute_child
    raise child_exception_type(errno_num, err_msg, err_filename)
PermissionError: [Errno 13] Permission denied: 'hive'
[2025-03-19T12:05:45.480+0000] {taskinstance.py:1398} INFO - Marking task as UP_FOR_RETRY. dag_id=fraud_detection_pipeline, task_id=run_fraud_detection, execution_date=20231007T220000, start_date=20250319T120545, end_date=20250319T120545
[2025-03-19T12:05:45.497+0000] {standard_task_runner.py:104} ERROR - Failed to execute job 496 for task run_fraud_detection ([Errno 13] Permission denied: 'hive'; 3754)
[2025-03-19T12:05:45.536+0000] {local_task_job_runner.py:228} INFO - Task exited with return code 1
[2025-03-19T12:05:45.572+0000] {taskinstance.py:2776} INFO - 0 downstream tasks scheduled from follow-on schedule check
